<mujoco><include file="scene_without_walls.xml" /><worldbody><body name="Fleet1Tenth_0" pos="0.0 0.0 .052388" quat="0.9485664043524404 0 0 0.31657823130133655"><inertial pos="0 0 0" diaginertia=".05 .05 .08" mass="3.0" /><joint name="Fleet1Tenth_0" type="free" /><site name="Fleet1Tenth_0_cog" pos="0 0 0" /><geom name="Fleet1Tenth_0_chassis_b" type="box" contype="0" conaffinity="0" size=".10113 .1016 .02" pos="-.06 0 0" rgba="0.85 0.2 0.2 1.0" /><geom name="Fleet1Tenth_0_chassis_f" type="box" contype="0" conaffinity="0" size=".06 .07 .02" pos=".10113 0 0" rgba="0.85 0.2 0.2 1.0" /><geom name="Fleet1Tenth_0_front" type="box" contype="0" conaffinity="0" size=".052388 .02 .02" pos=".2135 0 0" rgba="0.85 0.2 0.2 1.0" /><geom name="Fleet1Tenth_0_back" type="box" contype="0" conaffinity="0" size=".052388 .02 .02" pos="-.2135 0 0" rgba="0.85 0.2 0.2 1.0" /><geom name="Fleet1Tenth_0_front_bumper" type="box" contype="0" conaffinity="0" size=".005 .09 .02" pos=".265888 0 0.02" rgba="0.85 0.2 0.2 1.0" /><geom name="Fleet1Tenth_0_back_bumper" type="box" contype="0" conaffinity="0" size=".005 .08 .02" pos="-.265888 0 0.02" rgba="0.85 0.2 0.2 1.0" /><geom name="Fleet1Tenth_0_number" type="cylinder" contype="0" conaffinity="0" size=".01984 .03" pos=".12 0 .05" rgba="0.1 0.1 0.1 1.0" /><geom name="Fleet1Tenth_0_camera" type="box" contype="0" conaffinity="0" size=".012 .06 0.02" pos=".18 0 .08" /><geom name="Fleet1Tenth_0_camera_holder" type="box" contype="0" conaffinity="0" size=".012 .008 .02" pos=".18 0 .04" /><geom name="Fleet1Tenth_0_circuits" type="box" contype="0" conaffinity="0" size=".08 .06 .03" pos="-.05 0 .05" rgba="0.85 0.2 0.2 1.0" /><geom name="Fleet1Tenth_0_antennal" type="box" contype="0" conaffinity="0" size=".007 .004 .06" pos="-.16 -.01 .105" euler="0.2 0 0" rgba=".1 .1 .1 1.0" /><geom name="Fleet1Tenth_0_antennar" type="box" contype="0" conaffinity="0" size=".007 .004 .06" pos="-.16 .01 .105" euler="-0.2 0 0" rgba=".1 .1 .1 1.0" /><geom name="Fleet1Tenth_0_antenna_holder" type="box" contype="0" conaffinity="0" size=".008 .008 .02" pos="-.16 0 .04" rgba=".1 .1 .1 1.0" /><body name="Fleet1Tenth_0_wheelfl"><joint name="Fleet1Tenth_0_wheelfl_steer" type="hinge" pos="0.16113 .10016 0" limited="true" frictionloss="0.2" damping="0.2" armature="0.001" range="-0.6 0.6" axis="0 0 1" /><joint name="Fleet1Tenth_0_wheelfl" type="hinge" pos="0.16113 .122385 0" axis="0 1 0" frictionloss="0.01" damping="0.00001" armature="0.05" limited="false" /><geom name="Fleet1Tenth_0_wheelfl" type="cylinder" contype="0" conaffinity="0" size=".052388 .022225" pos="0.16113 .122385 0" mass="0.1" material="material_check" euler="1.571 0 0" /></body><body name="Fleet1Tenth_0_wheelrl"><joint name="Fleet1Tenth_0_wheelrl" type="hinge" pos="-0.16113 .122385 0" axis="0 1 0" frictionloss="0.01" damping="0.00001" armature="0.05" limited="false" /><geom name="Fleet1Tenth_0_wheelrl" type="cylinder" contype="0" conaffinity="0" size=".052388 .022225" pos="-0.16113 .122385 0" mass="0.1" material="material_check" euler="1.571 0 0" /></body><body name="Fleet1Tenth_0_wheelfr"><joint name="Fleet1Tenth_0_wheelfr_steer" type="hinge" pos="0.16113 -.10016 0" limited="true" frictionloss="0.2" damping="0.2" armature="0.001" range="-0.6 0.6" axis="0 0 1" /><joint name="Fleet1Tenth_0_wheelfr" type="hinge" pos="0.16113 -.122385 0" axis="0 1 0" frictionloss="0.01" damping="0.00001" armature="0.05" limited="false" /><geom name="Fleet1Tenth_0_wheelfr" type="cylinder" contype="0" conaffinity="0" size=".052388 .022225" pos="0.16113 -.122385 0" mass="0.1" material="material_check" euler="1.571 0 0" /></body><body name="Fleet1Tenth_0_wheelrr"><joint name="Fleet1Tenth_0_wheelrr" type="hinge" pos="-0.16113 -.122385 0" axis="0 1 0" frictionloss="0.01" damping="0.00001" armature="0.05" limited="false" /><geom name="Fleet1Tenth_0_wheelrr" type="cylinder" contype="0" conaffinity="0" size=".052388 .022225" pos="-0.16113 -.122385 0" mass="0.1" material="material_check" euler="1.571 0 0" /></body></body><body name="mpcc_0" mocap="true" pos="0 0 1" quat="0.9485664043524404 0 0 0.31657823130133655"><geom name="mpcc_marker0" type="sphere" contype="0" conaffinity="0" size="0.1" pos="0 0 0" rgba="0.2 0.2 0.85 1.0" /></body><body name="mpcc_1" mocap="true" pos="1 0 1" quat="0.9485664043524404 0 0 0.31657823130133655"><geom name="mpcc_marker1" type="sphere" contype="0" conaffinity="0" size="0.1" pos="0 0 0" rgba="0.2 0.2 0.85 1.0" /></body><body name="mpcc_2" mocap="true" pos="2 0 1" quat="0.9485664043524404 0 0 0.31657823130133655"><geom name="mpcc_marker2" type="sphere" contype="0" conaffinity="0" size="0.1" pos="0 0 0" rgba="0.2 0.2 0.85 1.0" /></body><body name="mpcc_3" mocap="true" pos="3 0 1" quat="0.9485664043524404 0 0 0.31657823130133655"><geom name="mpcc_marker3" type="sphere" contype="0" conaffinity="0" size="0.1" pos="0 0 0" rgba="0.2 0.2 0.85 1.0" /></body><body name="mpcc_4" mocap="true" pos="4 0 1" quat="0.9485664043524404 0 0 0.31657823130133655"><geom name="mpcc_marker4" type="sphere" contype="0" conaffinity="0" size="0.1" pos="0 0 0" rgba="0.2 0.2 0.85 1.0" /></body><body name="mpcc_5" mocap="true" pos="5 0 1" quat="0.9485664043524404 0 0 0.31657823130133655"><geom name="mpcc_marker5" type="sphere" contype="0" conaffinity="0" size="0.1" pos="0 0 0" rgba="0.2 0.2 0.85 1.0" /></body><body name="mpcc_6" mocap="true" pos="6 0 1" quat="0.9485664043524404 0 0 0.31657823130133655"><geom name="mpcc_marker6" type="sphere" contype="0" conaffinity="0" size="0.1" pos="0 0 0" rgba="0.2 0.2 0.85 1.0" /></body><body name="mpcc_7" mocap="true" pos="7 0 1" quat="0.9485664043524404 0 0 0.31657823130133655"><geom name="mpcc_marker7" type="sphere" contype="0" conaffinity="0" size="0.1" pos="0 0 0" rgba="0.2 0.2 0.85 1.0" /></body><body name="mpcc_8" mocap="true" pos="8 0 1" quat="0.9485664043524404 0 0 0.31657823130133655"><geom name="mpcc_marker8" type="sphere" contype="0" conaffinity="0" size="0.1" pos="0 0 0" rgba="0.2 0.2 0.85 1.0" /></body><body name="mpcc_9" mocap="true" pos="9 0 1" quat="0.9485664043524404 0 0 0.31657823130133655"><geom name="mpcc_marker9" type="sphere" contype="0" conaffinity="0" size="0.1" pos="0 0 0" rgba="0.2 0.2 0.85 1.0" /></body><body name="mpcc_10" mocap="true" pos="10 0 1" quat="0.9485664043524404 0 0 0.31657823130133655"><geom name="mpcc_marker10" type="sphere" contype="0" conaffinity="0" size="0.1" pos="0 0 0" rgba="0.2 0.2 0.85 1.0" /></body><body name="mpcc_11" mocap="true" pos="11 0 1" quat="0.9485664043524404 0 0 0.31657823130133655"><geom name="mpcc_marker11" type="sphere" contype="0" conaffinity="0" size="0.1" pos="0 0 0" rgba="0.2 0.2 0.85 1.0" /></body><body name="mpcc_12" mocap="true" pos="12 0 1" quat="0.9485664043524404 0 0 0.31657823130133655"><geom name="mpcc_marker12" type="sphere" contype="0" conaffinity="0" size="0.1" pos="0 0 0" rgba="0.2 0.2 0.85 1.0" /></body><body name="mpcc_13" mocap="true" pos="13 0 1" quat="0.9485664043524404 0 0 0.31657823130133655"><geom name="mpcc_marker13" type="sphere" contype="0" conaffinity="0" size="0.1" pos="0 0 0" rgba="0.2 0.2 0.85 1.0" /></body><body name="mpcc_14" mocap="true" pos="14 0 1" quat="0.9485664043524404 0 0 0.31657823130133655"><geom name="mpcc_marker14" type="sphere" contype="0" conaffinity="0" size="0.1" pos="0 0 0" rgba="0.2 0.2 0.85 1.0" /></body><body name="mpcc_15" mocap="true" pos="15 0 1" quat="0.9485664043524404 0 0 0.31657823130133655"><geom name="mpcc_marker15" type="sphere" contype="0" conaffinity="0" size="0.1" pos="0 0 0" rgba="0.2 0.2 0.85 1.0" /></body><body name="ref_trajectory_body" mocap="true" pos="0 0 0"><geom type="sphere" size="0.05" contype="0" conaffinity="0" rgba="0.1 0.1 0.1 1.0" pos="-0.0001820038520133303 0.0005823596250676052 0" /><geom type="sphere" size="0.05" contype="0" conaffinity="0" rgba="0.1 0.1 0.1 1.0" pos="0.5540052959930537 0.6089824611350859 0" /><geom type="sphere" size="0.05" contype="0" conaffinity="0" rgba="0.1 0.1 0.1 1.0" pos="0.8273250129434981 0.9233494645817409 0" /><geom type="sphere" size="0.05" contype="0" conaffinity="0" rgba="0.1 0.1 0.1 1.0" pos="0.9639646167337743 1.130427088135252 0" /><geom type="sphere" size="0.05" contype="0" conaffinity="0" rgba="0.1 0.1 0.1 1.0" pos="1.046175310917803 1.3380661253704025 0" /><geom type="sphere" size="0.05" contype="0" conaffinity="0" rgba="0.1 0.1 0.1 1.0" pos="1.0946994127614784 1.5757171471575377 0" /><geom type="sphere" size="0.05" contype="0" conaffinity="0" rgba="0.1 0.1 0.1 1.0" pos="1.0901326887802338 1.8190579193301837 0" /><geom type="sphere" size="0.05" contype="0" conaffinity="0" rgba="0.1 0.1 0.1 1.0" pos="1.0260861581622593 2.0513517130727474 0" /><geom type="sphere" size="0.05" contype="0" conaffinity="0" rgba="0.1 0.1 0.1 1.0" pos="0.9114627306200945 2.2674771375526377 0" /><geom type="sphere" size="0.05" contype="0" conaffinity="0" rgba="0.1 0.1 0.1 1.0" pos="0.7523915572012354 2.455488098444414 0" /><geom type="sphere" size="0.05" contype="0" conaffinity="0" rgba="0.1 0.1 0.1 1.0" pos="0.5546669115160252 2.602372340804823 0" /><geom type="sphere" size="0.05" contype="0" conaffinity="0" rgba="0.1 0.1 0.1 1.0" pos="0.3281822471239171 2.7011848524242494 0" /><geom type="sphere" size="0.05" contype="0" conaffinity="0" rgba="0.1 0.1 0.1 1.0" pos="0.08536198118211528 2.7475849911970545 0" /><geom type="sphere" size="0.05" contype="0" conaffinity="0" rgba="0.1 0.1 0.1 1.0" pos="-0.16021479377180994 2.7387111996872937 0" /><geom type="sphere" size="0.05" contype="0" conaffinity="0" rgba="0.1 0.1 0.1 1.0" pos="-0.3948271592290348 2.6762970027346102 0" /><geom type="sphere" size="0.05" contype="0" conaffinity="0" rgba="0.1 0.1 0.1 1.0" pos="-0.606087891161793 2.564708604163144 0" /><geom type="sphere" size="0.05" contype="0" conaffinity="0" rgba="0.1 0.1 0.1 1.0" pos="-0.7849841627384782 2.4065043515815168 0" /><geom type="sphere" size="0.05" contype="0" conaffinity="0" rgba="0.1 0.1 0.1 1.0" pos="-0.9258741783966756 2.2120563185404745 0" /><geom type="sphere" size="0.05" contype="0" conaffinity="0" rgba="0.1 0.1 0.1 1.0" pos="-1.0263303017631953 2.0041875531437836 0" /><geom type="sphere" size="0.05" contype="0" conaffinity="0" rgba="0.1 0.1 0.1 1.0" pos="-1.0886475828941167 1.7782210510676906 0" /><geom type="sphere" size="0.05" contype="0" conaffinity="0" rgba="0.1 0.1 0.1 1.0" pos="-1.1194944993154519 1.4979904860683957 0" /><geom type="sphere" size="0.05" contype="0" conaffinity="0" rgba="0.1 0.1 0.1 1.0" pos="-1.1253178993690451 1.1718583682847536 0" /><geom type="sphere" size="0.05" contype="0" conaffinity="0" rgba="0.1 0.1 0.1 1.0" pos="-1.113006694763619 0.8465299128504785 0" /><geom type="sphere" size="0.05" contype="0" conaffinity="0" rgba="0.1 0.1 0.1 1.0" pos="-1.094515372690197 0.5350346925837668 0" /><geom type="sphere" size="0.05" contype="0" conaffinity="0" rgba="0.1 0.1 0.1 1.0" pos="-1.0817849829788202 0.22669130982104785 0" /><geom type="sphere" size="0.05" contype="0" conaffinity="0" rgba="0.1 0.1 0.1 1.0" pos="-1.0795896632673276 -0.081209146492397 0" /><geom type="sphere" size="0.05" contype="0" conaffinity="0" rgba="0.1 0.1 0.1 1.0" pos="-1.0885356881827462 -0.38622478281910144 0" /><geom type="sphere" size="0.05" contype="0" conaffinity="0" rgba="0.1 0.1 0.1 1.0" pos="-1.1066614594652315 -0.6881044732776168 0" /><geom type="sphere" size="0.05" contype="0" conaffinity="0" rgba="0.1 0.1 0.1 1.0" pos="-1.1241857475052532 -0.9983373753076795 0" /><geom type="sphere" size="0.05" contype="0" conaffinity="0" rgba="0.1 0.1 0.1 1.0" pos="-1.1262399456023953 -1.3264411873095556 0" /><geom type="sphere" size="0.05" contype="0" conaffinity="0" rgba="0.1 0.1 0.1 1.0" pos="-1.1051110020404538 -1.639067586601308 0" /><geom type="sphere" size="0.05" contype="0" conaffinity="0" rgba="0.1 0.1 0.1 1.0" pos="-1.0578425375716591 -1.896957010376302 0" /><geom type="sphere" size="0.05" contype="0" conaffinity="0" rgba="0.1 0.1 0.1 1.0" pos="-0.9784583350593253 -2.1181399016086195 0" /><geom type="sphere" size="0.05" contype="0" conaffinity="0" rgba="0.1 0.1 0.1 1.0" pos="-0.8610049543600411 -2.325815225852054 0" /><geom type="sphere" size="0.05" contype="0" conaffinity="0" rgba="0.1 0.1 0.1 1.0" pos="-0.7033042658449717 -2.5028115897066443 0" /><geom type="sphere" size="0.05" contype="0" conaffinity="0" rgba="0.1 0.1 0.1 1.0" pos="-0.5074732502934403 -2.631389470930397 0" /><geom type="sphere" size="0.05" contype="0" conaffinity="0" rgba="0.1 0.1 0.1 1.0" pos="-0.28032935417618277 -2.710339560019328 0" /><geom type="sphere" size="0.05" contype="0" conaffinity="0" rgba="0.1 0.1 0.1 1.0" pos="-0.034119554519669575 -2.7388682609459183 0" /><geom type="sphere" size="0.05" contype="0" conaffinity="0" rgba="0.1 0.1 0.1 1.0" pos="0.21505367853467303 -2.715371231639838 0" /><geom type="sphere" size="0.05" contype="0" conaffinity="0" rgba="0.1 0.1 0.1 1.0" pos="0.4505466259984582 -2.6436846589077736 0" /><geom type="sphere" size="0.05" contype="0" conaffinity="0" rgba="0.1 0.1 0.1 1.0" pos="0.658326490552268 -2.527652770032141 0" /><geom type="sphere" size="0.05" contype="0" conaffinity="0" rgba="0.1 0.1 0.1 1.0" pos="0.8294642354957822 -2.3670363030226538 0" /><geom type="sphere" size="0.05" contype="0" conaffinity="0" rgba="0.1 0.1 0.1 1.0" pos="0.9593790452524809 -2.1727451787819505 0" /><geom type="sphere" size="0.05" contype="0" conaffinity="0" rgba="0.1 0.1 0.1 1.0" pos="1.047521247693698 -1.9632621969767678 0" /><geom type="sphere" size="0.05" contype="0" conaffinity="0" rgba="0.1 0.1 0.1 1.0" pos="1.098298439153303 -1.7213184894106146 0" /><geom type="sphere" size="0.05" contype="0" conaffinity="0" rgba="0.1 0.1 0.1 1.0" pos="1.1196147447149307 -1.416751244624808 0" /><geom type="sphere" size="0.05" contype="0" conaffinity="0" rgba="0.1 0.1 0.1 1.0" pos="1.1193692978554433 -1.0799461776851556 0" /><geom type="sphere" size="0.05" contype="0" conaffinity="0" rgba="0.1 0.1 0.1 1.0" pos="1.1063866838749141 -0.7589741847281889 0" /><geom type="sphere" size="0.05" contype="0" conaffinity="0" rgba="0.1 0.1 0.1 1.0" pos="1.0916836719467067 -0.4545215139449683 0" /><geom type="sphere" size="0.05" contype="0" conaffinity="0" rgba="0.1 0.1 0.1 1.0" pos="1.0833027096851666 -0.15160638748072328 0" /><geom type="sphere" size="0.05" contype="0" conaffinity="0" rgba="0.1 0.1 0.1 1.0" pos="1.083572008506082 0.15351726403249435 0" /><geom type="sphere" size="0.05" contype="0" conaffinity="0" rgba="0.1 0.1 0.1 1.0" pos="1.093353495660223 0.45853567641265147 0" /><geom type="sphere" size="0.05" contype="0" conaffinity="0" rgba="0.1 0.1 0.1 1.0" pos="1.1108520088139553 0.763240855976702 0" /><geom type="sphere" size="0.05" contype="0" conaffinity="0" rgba="0.1 0.1 0.1 1.0" pos="1.1248342767766093 1.0802961402050686 0" /><geom type="sphere" size="0.05" contype="0" conaffinity="0" rgba="0.1 0.1 0.1 1.0" pos="1.121265099521789 1.4103672114491148 0" /><geom type="sphere" size="0.05" contype="0" conaffinity="0" rgba="0.1 0.1 0.1 1.0" pos="1.0942410088162164 1.71064549614636 0" /><geom type="sphere" size="0.05" contype="0" conaffinity="0" rgba="0.1 0.1 0.1 1.0" pos="1.0401711767838018 1.9544428978254367 0" /><geom type="sphere" size="0.05" contype="0" conaffinity="0" rgba="0.1 0.1 0.1 1.0" pos="0.9525294008641213 2.1701977042288365 0" /><geom type="sphere" size="0.05" contype="0" conaffinity="0" rgba="0.1 0.1 0.1 1.0" pos="0.826216779374219 2.3716912052323034 0" /><geom type="sphere" size="0.05" contype="0" conaffinity="0" rgba="0.1 0.1 0.1 1.0" pos="0.660025463987515 2.537412067050302 0" /><geom type="sphere" size="0.05" contype="0" conaffinity="0" rgba="0.1 0.1 0.1 1.0" pos="0.45684240808421356 2.654528491107918 0" /><geom type="sphere" size="0.05" contype="0" conaffinity="0" rgba="0.1 0.1 0.1 1.0" pos="0.22427793612193866 2.722992160630461 0" /><geom type="sphere" size="0.05" contype="0" conaffinity="0" rgba="0.1 0.1 0.1 1.0" pos="-0.024635021298992383 2.7407319191008543 0" /><geom type="sphere" size="0.05" contype="0" conaffinity="0" rgba="0.1 0.1 0.1 1.0" pos="-0.2742370205373062 2.7061356322802936 0" /><geom type="sphere" size="0.05" contype="0" conaffinity="0" rgba="0.1 0.1 0.1 1.0" pos="-0.5091488236689083 2.62220532143508 0" /><geom type="sphere" size="0.05" contype="0" conaffinity="0" rgba="0.1 0.1 0.1 1.0" pos="-0.7145770010258164 2.4923880475929505 0" /><geom type="sphere" size="0.05" contype="0" conaffinity="0" rgba="0.1 0.1 0.1 1.0" pos="-0.8785113097118005 2.3202736520332556 0" /><geom type="sphere" size="0.05" contype="0" conaffinity="0" rgba="0.1 0.1 0.1 1.0" pos="-0.9983924396113552 2.1169895942309207 0" /><geom type="sphere" size="0.05" contype="0" conaffinity="0" rgba="0.1 0.1 0.1 1.0" pos="-1.0729446709218067 1.8940750599451293 0" /><geom type="sphere" size="0.05" contype="0" conaffinity="0" rgba="0.1 0.1 0.1 1.0" pos="-1.0851226973878478 1.6475426204285115 0" /><geom type="sphere" size="0.05" contype="0" conaffinity="0" rgba="0.1 0.1 0.1 1.0" pos="-1.040053878597313 1.3917864710849208 0" /><geom type="sphere" size="0.05" contype="0" conaffinity="0" rgba="0.1 0.1 0.1 1.0" pos="-0.9920638984482089 1.1829669794417974 0" /><geom type="sphere" size="0.05" contype="0" conaffinity="0" rgba="0.1 0.1 0.1 1.0" pos="-0.9054035707543056 0.9881633983334058 0" /><geom type="sphere" size="0.05" contype="0" conaffinity="0" rgba="0.1 0.1 0.1 1.0" pos="-0.6243606212388808 0.65480545247156 0" /><geom type="sphere" size="0.05" contype="0" conaffinity="0" rgba="0.1 0.1 0.1 1.0" pos="-0.13404980436739572 0.14592025855885885 0" /><geom type="sphere" size="0.05" contype="0" conaffinity="0" rgba="0.1 0.1 0.1 1.0" pos="0.39957605879173536 -0.4127549038395181 0" /><geom type="sphere" size="0.05" contype="0" conaffinity="0" rgba="0.1 0.1 0.1 1.0" pos="0.7905753154356997 -0.854654509231882 0" /><geom type="sphere" size="0.05" contype="0" conaffinity="0" rgba="0.1 0.1 0.1 1.0" pos="0.9576588206612259 -1.103222173881238 0" /><geom type="sphere" size="0.05" contype="0" conaffinity="0" rgba="0.1 0.1 0.1 1.0" pos="1.0146252460549459 -1.282569635517216 0" /><geom type="sphere" size="0.05" contype="0" conaffinity="0" rgba="0.1 0.1 0.1 1.0" pos="1.070976385391008 -1.512914529381039 0" /><geom type="sphere" size="0.05" contype="0" conaffinity="0" rgba="0.1 0.1 0.1 1.0" pos="1.0925601163119936 -1.764365318062259 0" /><geom type="sphere" size="0.05" contype="0" conaffinity="0" rgba="0.1 0.1 0.1 1.0" pos="1.0441368307622048 -1.9972095726209311 0" /><geom type="sphere" size="0.05" contype="0" conaffinity="0" rgba="0.1 0.1 0.1 1.0" pos="0.9419200449957511 -2.2148901662020757 0" /><geom type="sphere" size="0.05" contype="0" conaffinity="0" rgba="0.1 0.1 0.1 1.0" pos="0.7973363159485344 -2.4113601851197606 0" /><geom type="sphere" size="0.05" contype="0" conaffinity="0" rgba="0.1 0.1 0.1 1.0" pos="0.6116163720793103 -2.5688990904890447 0" /><geom type="sphere" size="0.05" contype="0" conaffinity="0" rgba="0.1 0.1 0.1 1.0" pos="0.39302194505402055 -2.678716558460733 0" /><geom type="sphere" size="0.05" contype="0" conaffinity="0" rgba="0.1 0.1 0.1 1.0" pos="0.15434127982243911 -2.737892201776797 0" /><geom type="sphere" size="0.05" contype="0" conaffinity="0" rgba="0.1 0.1 0.1 1.0" pos="-0.09201042066898675 -2.743773176807975 0" /><geom type="sphere" size="0.05" contype="0" conaffinity="0" rgba="0.1 0.1 0.1 1.0" pos="-0.3335155509634608 -2.6962420033002235 0" /><geom type="sphere" size="0.05" contype="0" conaffinity="0" rgba="0.1 0.1 0.1 1.0" pos="-0.5574585233833119 -2.5984906913085197 0" /><geom type="sphere" size="0.05" contype="0" conaffinity="0" rgba="0.1 0.1 0.1 1.0" pos="-0.7522397499635137 -2.4546401656150736 0" /><geom type="sphere" size="0.05" contype="0" conaffinity="0" rgba="0.1 0.1 0.1 1.0" pos="-0.9088601397732963 -2.2706704795453994 0" /><geom type="sphere" size="0.05" contype="0" conaffinity="0" rgba="0.1 0.1 0.1 1.0" pos="-1.0224267284844872 -2.0571798225374396 0" /><geom type="sphere" size="0.05" contype="0" conaffinity="0" rgba="0.1 0.1 0.1 1.0" pos="-1.0872727621146663 -1.8239641068781087 0" /><geom type="sphere" size="0.05" contype="0" conaffinity="0" rgba="0.1 0.1 0.1 1.0" pos="-1.0940409540233005 -1.5763538500831662 0" /><geom type="sphere" size="0.05" contype="0" conaffinity="0" rgba="0.1 0.1 0.1 1.0" pos="-1.0477513769956812 -1.3340245113835272 0" /><geom type="sphere" size="0.05" contype="0" conaffinity="0" rgba="0.1 0.1 0.1 1.0" pos="-0.9660441477292692 -1.125725680742491 0" /><geom type="sphere" size="0.05" contype="0" conaffinity="0" rgba="0.1 0.1 0.1 1.0" pos="-0.8277994779913896 -0.9229872489924943 0" /><geom type="sphere" size="0.05" contype="0" conaffinity="0" rgba="0.1 0.1 0.1 1.0" pos="-0.5524823258247037 -0.613529699401384 0" /><geom type="sphere" size="0.05" contype="0" conaffinity="0" rgba="0.1 0.1 0.1 1.0" pos="0.00027084020270852857 -0.0007321477324578877 0" /></body></worldbody><contact><pair geom1="Fleet1Tenth_0_wheelfl" geom2="roundabout" condim="6" friction="2.5 2.5 .009 .0001 .0001" /><pair geom1="Fleet1Tenth_0_wheelfr" geom2="roundabout" condim="6" friction="2.5 2.5 .009 .0001 .0001" /><pair geom1="Fleet1Tenth_0_wheelrl" geom2="roundabout" condim="6" friction="2.5 2.5 .009 .0001 .0001" /><pair geom1="Fleet1Tenth_0_wheelrr" geom2="roundabout" condim="6" friction="2.5 2.5 .009 .0001 .0001" /><exclude name="car_marker_exc0" body1="Fleet1Tenth_0" body2="mpcc_0" /><exclude name="car_marker_exc1" body1="Fleet1Tenth_0" body2="mpcc_1" /><exclude name="car_marker_exc2" body1="Fleet1Tenth_0" body2="mpcc_2" /><exclude name="car_marker_exc3" body1="Fleet1Tenth_0" body2="mpcc_3" /><exclude name="car_marker_exc4" body1="Fleet1Tenth_0" body2="mpcc_4" /><exclude name="car_marker_exc5" body1="Fleet1Tenth_0" body2="mpcc_5" /><exclude name="car_marker_exc6" body1="Fleet1Tenth_0" body2="mpcc_6" /><exclude name="car_marker_exc7" body1="Fleet1Tenth_0" body2="mpcc_7" /><exclude name="car_marker_exc8" body1="Fleet1Tenth_0" body2="mpcc_8" /><exclude name="car_marker_exc9" body1="Fleet1Tenth_0" body2="mpcc_9" /><exclude name="car_marker_exc10" body1="Fleet1Tenth_0" body2="mpcc_10" /><exclude name="car_marker_exc11" body1="Fleet1Tenth_0" body2="mpcc_11" /><exclude name="car_marker_exc12" body1="Fleet1Tenth_0" body2="mpcc_12" /><exclude name="car_marker_exc13" body1="Fleet1Tenth_0" body2="mpcc_13" /><exclude name="car_marker_exc14" body1="Fleet1Tenth_0" body2="mpcc_14" /><exclude name="car_marker_exc15" body1="Fleet1Tenth_0" body2="mpcc_15" /><exclude name="marker_exclude" body1="Fleet1Tenth_0" body2="ref_trajectory_body" /></contact><actuator><motor name="Fleet1Tenth_0_wheelfl_actr" joint="Fleet1Tenth_0_wheelfl" /><motor name="Fleet1Tenth_0_wheelfr_actr" joint="Fleet1Tenth_0_wheelfr" /><motor name="Fleet1Tenth_0_wheelrl_actr" joint="Fleet1Tenth_0_wheelrl" /><motor name="Fleet1Tenth_0_wheelrr_actr" joint="Fleet1Tenth_0_wheelrr" /><position forcelimited="true" forcerange="-5 5" name="Fleet1Tenth_0_wheelfl_actr_steer" joint="Fleet1Tenth_0_wheelfl_steer" kp="15" /><position forcelimited="true" forcerange="-5 5" name="Fleet1Tenth_0_wheelfr_actr_steer" joint="Fleet1Tenth_0_wheelfr_steer" kp="15" /></actuator><sensor><gyro site="Fleet1Tenth_0_cog" name="Fleet1Tenth_0_gyro" /><velocimeter site="Fleet1Tenth_0_cog" name="Fleet1Tenth_0_velocimeter" /><framepos objtype="site" objname="Fleet1Tenth_0_cog" name="Fleet1Tenth_0_posimeter" /><framequat objtype="site" objname="Fleet1Tenth_0_cog" name="Fleet1Tenth_0_orimeter" /><accelerometer site="Fleet1Tenth_0_cog" name="Fleet1Tenth_0_accelerometer" /></sensor><option><flag contact="enable" /></option></mujoco>