<mujoco><include file="scene_without_walls.xml" /><worldbody><body name="Fleet1Tenth_0" pos="0.1 0.0 .052388" quat="0.9238795325112867 0 0 0.3826834323650898"><inertial pos="0 0 0" diaginertia=".05 .05 .08" mass="3.0" /><joint name="Fleet1Tenth_0" type="free" /><site name="Fleet1Tenth_0_cog" pos="0 0 0" /><geom name="Fleet1Tenth_0_chassis_b" type="box" contype="0" conaffinity="0" size=".10113 .1016 .02" pos="-.06 0 0" rgba="0.85 0.2 0.2 1.0" /><geom name="Fleet1Tenth_0_chassis_f" type="box" contype="0" conaffinity="0" size=".06 .07 .02" pos=".10113 0 0" rgba="0.85 0.2 0.2 1.0" /><geom name="Fleet1Tenth_0_front" type="box" contype="0" conaffinity="0" size=".052388 .02 .02" pos=".2135 0 0" rgba="0.85 0.2 0.2 1.0" /><geom name="Fleet1Tenth_0_back" type="box" contype="0" conaffinity="0" size=".052388 .02 .02" pos="-.2135 0 0" rgba="0.85 0.2 0.2 1.0" /><geom name="Fleet1Tenth_0_front_bumper" type="box" contype="0" conaffinity="0" size=".005 .09 .02" pos=".265888 0 0.02" rgba="0.85 0.2 0.2 1.0" /><geom name="Fleet1Tenth_0_back_bumper" type="box" contype="0" conaffinity="0" size=".005 .08 .02" pos="-.265888 0 0.02" rgba="0.85 0.2 0.2 1.0" /><geom name="Fleet1Tenth_0_number" type="cylinder" contype="0" conaffinity="0" size=".01984 .03" pos=".12 0 .05" rgba="0.1 0.1 0.1 1.0" /><geom name="Fleet1Tenth_0_camera" type="box" contype="0" conaffinity="0" size=".012 .06 0.02" pos=".18 0 .08" /><geom name="Fleet1Tenth_0_camera_holder" type="box" contype="0" conaffinity="0" size=".012 .008 .02" pos=".18 0 .04" /><geom name="Fleet1Tenth_0_circuits" type="box" contype="0" conaffinity="0" size=".08 .06 .03" pos="-.05 0 .05" rgba="0.85 0.2 0.2 1.0" /><geom name="Fleet1Tenth_0_antennal" type="box" contype="0" conaffinity="0" size=".007 .004 .06" pos="-.16 -.01 .105" euler="0.2 0 0" rgba=".1 .1 .1 1.0" /><geom name="Fleet1Tenth_0_antennar" type="box" contype="0" conaffinity="0" size=".007 .004 .06" pos="-.16 .01 .105" euler="-0.2 0 0" rgba=".1 .1 .1 1.0" /><geom name="Fleet1Tenth_0_antenna_holder" type="box" contype="0" conaffinity="0" size=".008 .008 .02" pos="-.16 0 .04" rgba=".1 .1 .1 1.0" /><body name="Fleet1Tenth_0_wheelfl"><joint name="Fleet1Tenth_0_wheelfl_steer" type="hinge" pos="0.16113 .10016 0" limited="true" frictionloss="0.2" damping="0.2" armature="0.001" range="-0.6 0.6" axis="0 0 1" /><joint name="Fleet1Tenth_0_wheelfl" type="hinge" pos="0.16113 .122385 0" axis="0 1 0" frictionloss="0.01" damping="0.00001" armature="0.05" limited="false" /><geom name="Fleet1Tenth_0_wheelfl" type="cylinder" contype="0" conaffinity="0" size=".052388 .022225" pos="0.16113 .122385 0" mass="0.1" material="material_check" euler="1.571 0 0" /></body><body name="Fleet1Tenth_0_wheelrl"><joint name="Fleet1Tenth_0_wheelrl" type="hinge" pos="-0.16113 .122385 0" axis="0 1 0" frictionloss="0.01" damping="0.00001" armature="0.05" limited="false" /><geom name="Fleet1Tenth_0_wheelrl" type="cylinder" contype="0" conaffinity="0" size=".052388 .022225" pos="-0.16113 .122385 0" mass="0.1" material="material_check" euler="1.571 0 0" /></body><body name="Fleet1Tenth_0_wheelfr"><joint name="Fleet1Tenth_0_wheelfr_steer" type="hinge" pos="0.16113 -.10016 0" limited="true" frictionloss="0.2" damping="0.2" armature="0.001" range="-0.6 0.6" axis="0 0 1" /><joint name="Fleet1Tenth_0_wheelfr" type="hinge" pos="0.16113 -.122385 0" axis="0 1 0" frictionloss="0.01" damping="0.00001" armature="0.05" limited="false" /><geom name="Fleet1Tenth_0_wheelfr" type="cylinder" contype="0" conaffinity="0" size=".052388 .022225" pos="0.16113 -.122385 0" mass="0.1" material="material_check" euler="1.571 0 0" /></body><body name="Fleet1Tenth_0_wheelrr"><joint name="Fleet1Tenth_0_wheelrr" type="hinge" pos="-0.16113 -.122385 0" axis="0 1 0" frictionloss="0.01" damping="0.00001" armature="0.05" limited="false" /><geom name="Fleet1Tenth_0_wheelrr" type="cylinder" contype="0" conaffinity="0" size=".052388 .022225" pos="-0.16113 -.122385 0" mass="0.1" material="material_check" euler="1.571 0 0" /></body></body><body name="mpcc_0" mocap="true" pos="0 0 1" quat="0.9485664043524404 0 0 0.31657823130133655"><geom name="mpcc_marker0" type="sphere" contype="0" conaffinity="0" size="0.1" pos="0 0 0" rgba="0.2 0.2 0.85 1.0" /></body><body name="mpcc_1" mocap="true" pos="1 0 1" quat="0.9485664043524404 0 0 0.31657823130133655"><geom name="mpcc_marker1" type="sphere" contype="0" conaffinity="0" size="0.1" pos="0 0 0" rgba="0.2 0.2 0.85 1.0" /></body><body name="mpcc_2" mocap="true" pos="2 0 1" quat="0.9485664043524404 0 0 0.31657823130133655"><geom name="mpcc_marker2" type="sphere" contype="0" conaffinity="0" size="0.1" pos="0 0 0" rgba="0.2 0.2 0.85 1.0" /></body><body name="mpcc_3" mocap="true" pos="3 0 1" quat="0.9485664043524404 0 0 0.31657823130133655"><geom name="mpcc_marker3" type="sphere" contype="0" conaffinity="0" size="0.1" pos="0 0 0" rgba="0.2 0.2 0.85 1.0" /></body><body name="mpcc_4" mocap="true" pos="4 0 1" quat="0.9485664043524404 0 0 0.31657823130133655"><geom name="mpcc_marker4" type="sphere" contype="0" conaffinity="0" size="0.1" pos="0 0 0" rgba="0.2 0.2 0.85 1.0" /></body><body name="mpcc_5" mocap="true" pos="5 0 1" quat="0.9485664043524404 0 0 0.31657823130133655"><geom name="mpcc_marker5" type="sphere" contype="0" conaffinity="0" size="0.1" pos="0 0 0" rgba="0.2 0.2 0.85 1.0" /></body><body name="mpcc_6" mocap="true" pos="6 0 1" quat="0.9485664043524404 0 0 0.31657823130133655"><geom name="mpcc_marker6" type="sphere" contype="0" conaffinity="0" size="0.1" pos="0 0 0" rgba="0.2 0.2 0.85 1.0" /></body><body name="mpcc_7" mocap="true" pos="7 0 1" quat="0.9485664043524404 0 0 0.31657823130133655"><geom name="mpcc_marker7" type="sphere" contype="0" conaffinity="0" size="0.1" pos="0 0 0" rgba="0.2 0.2 0.85 1.0" /></body><body name="mpcc_8" mocap="true" pos="8 0 1" quat="0.9485664043524404 0 0 0.31657823130133655"><geom name="mpcc_marker8" type="sphere" contype="0" conaffinity="0" size="0.1" pos="0 0 0" rgba="0.2 0.2 0.85 1.0" /></body><body name="mpcc_9" mocap="true" pos="9 0 1" quat="0.9485664043524404 0 0 0.31657823130133655"><geom name="mpcc_marker9" type="sphere" contype="0" conaffinity="0" size="0.1" pos="0 0 0" rgba="0.2 0.2 0.85 1.0" /></body><body name="mpcc_10" mocap="true" pos="10 0 1" quat="0.9485664043524404 0 0 0.31657823130133655"><geom name="mpcc_marker10" type="sphere" contype="0" conaffinity="0" size="0.1" pos="0 0 0" rgba="0.2 0.2 0.85 1.0" /></body><body name="mpcc_11" mocap="true" pos="11 0 1" quat="0.9485664043524404 0 0 0.31657823130133655"><geom name="mpcc_marker11" type="sphere" contype="0" conaffinity="0" size="0.1" pos="0 0 0" rgba="0.2 0.2 0.85 1.0" /></body><body name="mpcc_12" mocap="true" pos="12 0 1" quat="0.9485664043524404 0 0 0.31657823130133655"><geom name="mpcc_marker12" type="sphere" contype="0" conaffinity="0" size="0.1" pos="0 0 0" rgba="0.2 0.2 0.85 1.0" /></body><body name="mpcc_13" mocap="true" pos="13 0 1" quat="0.9485664043524404 0 0 0.31657823130133655"><geom name="mpcc_marker13" type="sphere" contype="0" conaffinity="0" size="0.1" pos="0 0 0" rgba="0.2 0.2 0.85 1.0" /></body><body name="mpcc_14" mocap="true" pos="14 0 1" quat="0.9485664043524404 0 0 0.31657823130133655"><geom name="mpcc_marker14" type="sphere" contype="0" conaffinity="0" size="0.1" pos="0 0 0" rgba="0.2 0.2 0.85 1.0" /></body><body name="ref_trajectory_body" mocap="true" pos="0 0 0"><geom type="sphere" size="0.05" contype="0" conaffinity="0" rgba="0.1 0.1 0.1 1.0" pos="0.01614453395341072 0.007054335505136806 0" /><geom type="sphere" size="0.05" contype="0" conaffinity="0" rgba="0.1 0.1 0.1 1.0" pos="0.051178157011020055 0.06351240846303886 0" /><geom type="sphere" size="0.05" contype="0" conaffinity="0" rgba="0.1 0.1 0.1 1.0" pos="0.08196768417987307 0.10864455779499044 0" /><geom type="sphere" size="0.05" contype="0" conaffinity="0" rgba="0.1 0.1 0.1 1.0" pos="0.10964452425259703 0.1448495551010317 0" /><geom type="sphere" size="0.05" contype="0" conaffinity="0" rgba="0.1 0.1 0.1 1.0" pos="0.13522822272567345 0.17430722076568383 0" /><geom type="sphere" size="0.05" contype="0" conaffinity="0" rgba="0.1 0.1 0.1 1.0" pos="0.1596264617994382 0.1989784239579488 0" /><geom type="sphere" size="0.05" contype="0" conaffinity="0" rgba="0.1 0.1 0.1 1.0" pos="0.18363506037808106 0.22060508263130907 0" /><geom type="sphere" size="0.05" contype="0" conaffinity="0" rgba="0.1 0.1 0.1 1.0" pos="0.20793797406964615 0.2407101635237282 0" /><geom type="sphere" size="0.05" contype="0" conaffinity="0" rgba="0.1 0.1 0.1 1.0" pos="0.2331072951860316 0.26059768215765033 0" /><geom type="sphere" size="0.05" contype="0" conaffinity="0" rgba="0.1 0.1 0.1 1.0" pos="0.2596032527429899 0.2813527028400004 0" /><geom type="sphere" size="0.05" contype="0" conaffinity="0" rgba="0.1 0.1 0.1 1.0" pos="0.2877742124601278 0.3038413386621845 0" /><geom type="sphere" size="0.05" contype="0" conaffinity="0" rgba="0.1 0.1 0.1 1.0" pos="0.31785667676090584 0.3287107515000887 0" /><geom type="sphere" size="0.05" contype="0" conaffinity="0" rgba="0.1 0.1 0.1 1.0" pos="0.3499752847726393 0.35638915201408067 0" /><geom type="sphere" size="0.05" contype="0" conaffinity="0" rgba="0.1 0.1 0.1 1.0" pos="0.384142812326497 0.3870857996490084 0" /><geom type="sphere" size="0.05" contype="0" conaffinity="0" rgba="0.1 0.1 0.1 1.0" pos="0.42026017195750276 0.42079100263420094 0" /><geom type="sphere" size="0.05" contype="0" conaffinity="0" rgba="0.1 0.1 0.1 1.0" pos="0.45811641290453314 0.45727611798346723 0" /><geom type="sphere" size="0.05" contype="0" conaffinity="0" rgba="0.1 0.1 0.1 1.0" pos="0.4973887211103212 0.4960935514950988 0" /><geom type="sphere" size="0.05" contype="0" conaffinity="0" rgba="0.1 0.1 0.1 1.0" pos="0.5376424192214518 0.5365767577518663 0" /><geom type="sphere" size="0.05" contype="0" conaffinity="0" rgba="0.1 0.1 0.1 1.0" pos="0.5783309665883652 0.5778402401210213 0" /><geom type="sphere" size="0.05" contype="0" conaffinity="0" rgba="0.1 0.1 0.1 1.0" pos="0.618795959265356 0.6187795507542975 0" /><geom type="sphere" size="0.05" contype="0" conaffinity="0" rgba="0.1 0.1 0.1 1.0" pos="0.658267130010572 0.6580712905879076 0" /><geom type="sphere" size="0.05" contype="0" conaffinity="0" rgba="0.1 0.1 0.1 1.0" pos="0.6958628297780691 0.6941740249007697 0" /><geom type="sphere" size="0.05" contype="0" conaffinity="0" rgba="0.1 0.1 0.1 1.0" pos="0.730674651432178 0.7254891954980648 0" /><geom type="sphere" size="0.05" contype="0" conaffinity="0" rgba="0.1 0.1 0.1 1.0" pos="0.7621117619530745 0.7510158691760324 0" /><geom type="sphere" size="0.05" contype="0" conaffinity="0" rgba="0.1 0.1 0.1 1.0" pos="0.7900521028300567 0.7706382456104943 0" /><geom type="sphere" size="0.05" contype="0" conaffinity="0" rgba="0.1 0.1 0.1 1.0" pos="0.8148461052779994 0.7851327218493173 0" /><geom type="sphere" size="0.05" contype="0" conaffinity="0" rgba="0.1 0.1 0.1 1.0" pos="0.8373166902373558 0.796167892312415 0" /><geom type="sphere" size="0.05" contype="0" conaffinity="0" rgba="0.1 0.1 0.1 1.0" pos="0.8587592683741582 0.8063045487917467 0" /><geom type="sphere" size="0.05" contype="0" conaffinity="0" rgba="0.1 0.1 0.1 1.0" pos="0.8809417400800155 0.8189956804513171 0" /><geom type="sphere" size="0.05" contype="0" conaffinity="0" rgba="0.1 0.1 0.1 1.0" pos="0.9061044790721662 0.8385864507996968 0" /><geom type="sphere" size="0.05" contype="0" conaffinity="0" rgba="0.1 0.1 0.1 1.0" pos="0.9368528143267989 0.8701632295247892 0" /><geom type="sphere" size="0.05" contype="0" conaffinity="0" rgba="0.1 0.1 0.1 1.0" pos="0.9753251262580724 0.9183855004942099 0" /><geom type="sphere" size="0.05" contype="0" conaffinity="0" rgba="0.1 0.1 0.1 1.0" pos="1.0225594806816405 0.9865965404402708 0" /><geom type="sphere" size="0.05" contype="0" conaffinity="0" rgba="0.1 0.1 0.1 1.0" pos="1.0784542525367244 1.0767681299781764 0" /><geom type="sphere" size="0.05" contype="0" conaffinity="0" rgba="0.1 0.1 0.1 1.0" pos="1.1417681258861119 1.189500553606021 0" /><geom type="sphere" size="0.05" contype="0" conaffinity="0" rgba="0.1 0.1 0.1 1.0" pos="1.2101200939161574 1.3240225997047899 0" /><geom type="sphere" size="0.05" contype="0" conaffinity="0" rgba="0.1 0.1 0.1 1.0" pos="1.279989458936784 1.478191560538361 0" /><geom type="sphere" size="0.05" contype="0" conaffinity="0" rgba="0.1 0.1 0.1 1.0" pos="1.3467158323814803 1.6484932322535024 0" /><geom type="sphere" size="0.05" contype="0" conaffinity="0" rgba="0.1 0.1 0.1 1.0" pos="1.4045580013353964 1.8300906286397611 0" /><geom type="sphere" size="0.05" contype="0" conaffinity="0" rgba="0.1 0.1 0.1 1.0" pos="1.4476407945557273 2.017607540232651 0" /><geom type="sphere" size="0.05" contype="0" conaffinity="0" rgba="0.1 0.1 0.1 1.0" pos="1.4711987574005159 2.2061577113998614 0" /><geom type="sphere" size="0.05" contype="0" conaffinity="0" rgba="0.1 0.1 0.1 1.0" pos="1.471736888587569 2.3914778546726847 0" /><geom type="sphere" size="0.05" contype="0" conaffinity="0" rgba="0.1 0.1 0.1 1.0" pos="1.4470306647119726 2.5699276710349848 0" /><geom type="sphere" size="0.05" contype="0" conaffinity="0" rgba="0.1 0.1 0.1 1.0" pos="1.3961260402460811 2.738489849923181 0" /><geom type="sphere" size="0.05" contype="0" conaffinity="0" rgba="0.1 0.1 0.1 1.0" pos="1.319339447539525 2.8947700692262557 0" /><geom type="sphere" size="0.05" contype="0" conaffinity="0" rgba="0.1 0.1 0.1 1.0" pos="1.218257796819207 3.036996995285746 0" /><geom type="sphere" size="0.05" contype="0" conaffinity="0" rgba="0.1 0.1 0.1 1.0" pos="1.0957290482860436 3.16401866062098 0" /><geom type="sphere" size="0.05" contype="0" conaffinity="0" rgba="0.1 0.1 0.1 1.0" pos="0.9554785190792529 3.2751550460390564 0" /><geom type="sphere" size="0.05" contype="0" conaffinity="0" rgba="0.1 0.1 0.1 1.0" pos="0.801235090117582 3.369862362412766 0" /><geom type="sphere" size="0.05" contype="0" conaffinity="0" rgba="0.1 0.1 0.1 1.0" pos="0.6365164610900158 3.447650543954614 0" /><geom type="sphere" size="0.05" contype="0" conaffinity="0" rgba="0.1 0.1 0.1 1.0" pos="0.46462792859950436 3.508082778770002 0" /><geom type="sphere" size="0.05" contype="0" conaffinity="0" rgba="0.1 0.1 0.1 1.0" pos="0.28866238616297774 3.550775508857233 0" /><geom type="sphere" size="0.05" contype="0" conaffinity="0" rgba="0.1 0.1 0.1 1.0" pos="0.11150032421133682 3.5753984301075064 0" /><geom type="sphere" size="0.05" contype="0" conaffinity="0" rgba="0.1 0.1 0.1 1.0" pos="-0.06419016991054781 3.581674492304923 0" /><geom type="sphere" size="0.05" contype="0" conaffinity="0" rgba="0.1 0.1 0.1 1.0" pos="-0.2359535018325143 3.5693800711978936 0" /><geom type="sphere" size="0.05" contype="0" conaffinity="0" rgba="0.1 0.1 0.1 1.0" pos="-0.4015623683730957 3.5383752105810204 0" /><geom type="sphere" size="0.05" contype="0" conaffinity="0" rgba="0.1 0.1 0.1 1.0" pos="-0.5590820401570153 3.4887266767229477 0" /><geom type="sphere" size="0.05" contype="0" conaffinity="0" rgba="0.1 0.1 0.1 1.0" pos="-0.7068985888820393 3.4207619930386475 0" /><geom type="sphere" size="0.05" contype="0" conaffinity="0" rgba="0.1 0.1 0.1 1.0" pos="-0.8437195809044981 3.3350707678009432 0" /><geom type="sphere" size="0.05" contype="0" conaffinity="0" rgba="0.1 0.1 0.1 1.0" pos="-0.9685740772393032 3.2325046941405025 0" /><geom type="sphere" size="0.05" contype="0" conaffinity="0" rgba="0.1 0.1 0.1 1.0" pos="-1.0808126335599342 3.114177550045843 0" /><geom type="sphere" size="0.05" contype="0" conaffinity="0" rgba="0.1 0.1 0.1 1.0" pos="-1.180107300198452 2.981465198363325 0" /><geom type="sphere" size="0.05" contype="0" conaffinity="0" rgba="0.1 0.1 0.1 1.0" pos="-1.2664516200006561 2.836005582810033 0" /><geom type="sphere" size="0.05" contype="0" conaffinity="0" rgba="0.1 0.1 0.1 1.0" pos="-1.340146566842124 2.679672588358067 0" /><geom type="sphere" size="0.05" contype="0" conaffinity="0" rgba="0.1 0.1 0.1 1.0" pos="-1.4016917471480246 2.514373790144544 0" /><geom type="sphere" size="0.05" contype="0" conaffinity="0" rgba="0.1 0.1 0.1 1.0" pos="-1.4517025666852037 2.341896470561549 0" /><geom type="sphere" size="0.05" contype="0" conaffinity="0" rgba="0.1 0.1 0.1 1.0" pos="-1.4909050808332327 2.163898046160133 0" /><geom type="sphere" size="0.05" contype="0" conaffinity="0" rgba="0.1 0.1 0.1 1.0" pos="-1.520135994584411 1.9819060676503137 0" /><geom type="sphere" size="0.05" contype="0" conaffinity="0" rgba="0.1 0.1 0.1 1.0" pos="-1.540342662543758 1.797318219901089 0" /><geom type="sphere" size="0.05" contype="0" conaffinity="0" rgba="0.1 0.1 0.1 1.0" pos="-1.5525830889290206 1.6114023219404323 0" /><geom type="sphere" size="0.05" contype="0" conaffinity="0" rgba="0.1 0.1 0.1 1.0" pos="-1.5580259275706712 1.425296326955271 0" /><geom type="sphere" size="0.05" contype="0" conaffinity="0" rgba="0.1 0.1 0.1 1.0" pos="-1.5579446272693203 1.2400061767479535 0" /><geom type="sphere" size="0.05" contype="0" conaffinity="0" rgba="0.1 0.1 0.1 1.0" pos="-1.553623260077013 1.0563712907438143 0" /><geom type="sphere" size="0.05" contype="0" conaffinity="0" rgba="0.1 0.1 0.1 1.0" pos="-1.5462328300853374 0.8750192370269413 0" /><geom type="sphere" size="0.05" contype="0" conaffinity="0" rgba="0.1 0.1 0.1 1.0" pos="-1.5368152871543788 0.6963598738713183 0" /><geom type="sphere" size="0.05" contype="0" conaffinity="0" rgba="0.1 0.1 0.1 1.0" pos="-1.5262835244742985 0.520585348847232 0" /><geom type="sphere" size="0.05" contype="0" conaffinity="0" rgba="0.1 0.1 0.1 1.0" pos="-1.5154213785653374 0.3476700988212768 0" /><geom type="sphere" size="0.05" contype="0" conaffinity="0" rgba="0.1 0.1 0.1 1.0" pos="-1.5048836292778143 0.17737084995635266 0" /><geom type="sphere" size="0.05" contype="0" conaffinity="0" rgba="0.1 0.1 0.1 1.0" pos="-1.4951959997921247 0.009226617711650141 0" /><geom type="sphere" size="0.05" contype="0" conaffinity="0" rgba="0.1 0.1 0.1 1.0" pos="-1.4867555361799158 -0.15743915803585024 0" /><geom type="sphere" size="0.05" contype="0" conaffinity="0" rgba="0.1 0.1 0.1 1.0" pos="-1.479846054632826 -0.32343171867143417 0" /><geom type="sphere" size="0.05" contype="0" conaffinity="0" rgba="0.1 0.1 0.1 1.0" pos="-1.4746733197991844 -0.4894871003677033 0" /><geom type="sphere" size="0.05" contype="0" conaffinity="0" rgba="0.1 0.1 0.1 1.0" pos="-1.4713736902765533 -0.6562235011415304 0" /><geom type="sphere" size="0.05" contype="0" conaffinity="0" rgba="0.1 0.1 0.1 1.0" pos="-1.4700141678028589 -0.8241410041423427 0" /><geom type="sphere" size="0.05" contype="0" conaffinity="0" rgba="0.1 0.1 0.1 1.0" pos="-1.4705923972563895 -0.9936215776520911 0" /><geom type="sphere" size="0.05" contype="0" conaffinity="0" rgba="0.1 0.1 0.1 1.0" pos="-1.4730366666557966 -1.164929075085274 0" /><geom type="sphere" size="0.05" contype="0" conaffinity="0" rgba="0.1 0.1 0.1 1.0" pos="-1.4772059071600927 -1.3382092349889259 0" /><geom type="sphere" size="0.05" contype="0" conaffinity="0" rgba="0.1 0.1 0.1 1.0" pos="-1.4828896930686553 -1.5134896810426237 0" /><geom type="sphere" size="0.05" contype="0" conaffinity="0" rgba="0.1 0.1 0.1 1.0" pos="-1.4898082418212226 -1.6906799220584727 0" /><geom type="sphere" size="0.05" contype="0" conaffinity="0" rgba="0.1 0.1 0.1 1.0" pos="-1.4976124139978966 -1.8695713519811332 0" /><geom type="sphere" size="0.05" contype="0" conaffinity="0" rgba="0.1 0.1 0.1 1.0" pos="-1.5058837133191418 -2.0498372498877906 0" /><geom type="sphere" size="0.05" contype="0" conaffinity="0" rgba="0.1 0.1 0.1 1.0" pos="-1.5141342866457843 -2.231032779988175 0" /><geom type="sphere" size="0.05" contype="0" conaffinity="0" rgba="0.1 0.1 0.1 1.0" pos="-1.521806923979014 -2.4125949916245544 0" /><geom type="sphere" size="0.05" contype="0" conaffinity="0" rgba="0.1 0.1 0.1 1.0" pos="-1.5282750584603826 -2.593842819271738 0" /><geom type="sphere" size="0.05" contype="0" conaffinity="0" rgba="0.1 0.1 0.1 1.0" pos="-1.532842766371805 -2.773977082537068 0" /><geom type="sphere" size="0.05" contype="0" conaffinity="0" rgba="0.1 0.1 0.1 1.0" pos="-1.5347447671355592 -2.9520804861604364 0" /><geom type="sphere" size="0.05" contype="0" conaffinity="0" rgba="0.1 0.1 0.1 1.0" pos="-1.5331464233142844 -3.127117620014256 0" /><geom type="sphere" size="0.05" contype="0" conaffinity="0" rgba="0.1 0.1 0.1 1.0" pos="-1.5271437406109838 -3.2979349591034923 0" /><geom type="sphere" size="0.05" contype="0" conaffinity="0" rgba="0.1 0.1 0.1 1.0" pos="-1.515763367869023 -3.463260863565647 0" /><geom type="sphere" size="0.05" contype="0" conaffinity="0" rgba="0.1 0.1 0.1 1.0" pos="-1.4979625970721282 -3.6217055786707704 0" /></body></worldbody><contact><pair geom1="Fleet1Tenth_0_wheelfl" geom2="roundabout" condim="6" friction="2.5 2.5 .009 .0001 .0001" /><pair geom1="Fleet1Tenth_0_wheelfr" geom2="roundabout" condim="6" friction="2.5 2.5 .009 .0001 .0001" /><pair geom1="Fleet1Tenth_0_wheelrl" geom2="roundabout" condim="6" friction="2.5 2.5 .009 .0001 .0001" /><pair geom1="Fleet1Tenth_0_wheelrr" geom2="roundabout" condim="6" friction="2.5 2.5 .009 .0001 .0001" /><exclude name="car_marker_exc0" body1="Fleet1Tenth_0" body2="mpcc_0" /><exclude name="car_marker_exc1" body1="Fleet1Tenth_0" body2="mpcc_1" /><exclude name="car_marker_exc2" body1="Fleet1Tenth_0" body2="mpcc_2" /><exclude name="car_marker_exc3" body1="Fleet1Tenth_0" body2="mpcc_3" /><exclude name="car_marker_exc4" body1="Fleet1Tenth_0" body2="mpcc_4" /><exclude name="car_marker_exc5" body1="Fleet1Tenth_0" body2="mpcc_5" /><exclude name="car_marker_exc6" body1="Fleet1Tenth_0" body2="mpcc_6" /><exclude name="car_marker_exc7" body1="Fleet1Tenth_0" body2="mpcc_7" /><exclude name="car_marker_exc8" body1="Fleet1Tenth_0" body2="mpcc_8" /><exclude name="car_marker_exc9" body1="Fleet1Tenth_0" body2="mpcc_9" /><exclude name="car_marker_exc10" body1="Fleet1Tenth_0" body2="mpcc_10" /><exclude name="car_marker_exc11" body1="Fleet1Tenth_0" body2="mpcc_11" /><exclude name="car_marker_exc12" body1="Fleet1Tenth_0" body2="mpcc_12" /><exclude name="car_marker_exc13" body1="Fleet1Tenth_0" body2="mpcc_13" /><exclude name="car_marker_exc14" body1="Fleet1Tenth_0" body2="mpcc_14" /><exclude name="marker_exclude" body1="Fleet1Tenth_0" body2="ref_trajectory_body" /></contact><actuator><motor name="Fleet1Tenth_0_wheelfl_actr" joint="Fleet1Tenth_0_wheelfl" /><motor name="Fleet1Tenth_0_wheelfr_actr" joint="Fleet1Tenth_0_wheelfr" /><motor name="Fleet1Tenth_0_wheelrl_actr" joint="Fleet1Tenth_0_wheelrl" /><motor name="Fleet1Tenth_0_wheelrr_actr" joint="Fleet1Tenth_0_wheelrr" /><position forcelimited="true" forcerange="-5 5" name="Fleet1Tenth_0_wheelfl_actr_steer" joint="Fleet1Tenth_0_wheelfl_steer" kp="15" /><position forcelimited="true" forcerange="-5 5" name="Fleet1Tenth_0_wheelfr_actr_steer" joint="Fleet1Tenth_0_wheelfr_steer" kp="15" /></actuator><sensor><gyro site="Fleet1Tenth_0_cog" name="Fleet1Tenth_0_gyro" /><velocimeter site="Fleet1Tenth_0_cog" name="Fleet1Tenth_0_velocimeter" /><framepos objtype="site" objname="Fleet1Tenth_0_cog" name="Fleet1Tenth_0_posimeter" /><framequat objtype="site" objname="Fleet1Tenth_0_cog" name="Fleet1Tenth_0_orimeter" /><accelerometer site="Fleet1Tenth_0_cog" name="Fleet1Tenth_0_accelerometer" /></sensor><option><flag contact="enable" /></option></mujoco>