<mujoco><include file="scene_without_walls.xml" /><worldbody><body name="Fleet1Tenth_0" pos="0.1 0.0 .052388" quat="0.9238795325112867 0 0 0.3826834323650898"><inertial pos="0 0 0" diaginertia=".05 .05 .08" mass="3.0" /><joint name="Fleet1Tenth_0" type="free" /><site name="Fleet1Tenth_0_cog" pos="0 0 0" /><geom name="Fleet1Tenth_0_chassis_b" type="box" contype="0" conaffinity="0" size=".10113 .1016 .02" pos="-.06 0 0" rgba="0.85 0.2 0.2 1.0" /><geom name="Fleet1Tenth_0_chassis_f" type="box" contype="0" conaffinity="0" size=".06 .07 .02" pos=".10113 0 0" rgba="0.85 0.2 0.2 1.0" /><geom name="Fleet1Tenth_0_front" type="box" contype="0" conaffinity="0" size=".052388 .02 .02" pos=".2135 0 0" rgba="0.85 0.2 0.2 1.0" /><geom name="Fleet1Tenth_0_back" type="box" contype="0" conaffinity="0" size=".052388 .02 .02" pos="-.2135 0 0" rgba="0.85 0.2 0.2 1.0" /><geom name="Fleet1Tenth_0_front_bumper" type="box" contype="0" conaffinity="0" size=".005 .09 .02" pos=".265888 0 0.02" rgba="0.85 0.2 0.2 1.0" /><geom name="Fleet1Tenth_0_back_bumper" type="box" contype="0" conaffinity="0" size=".005 .08 .02" pos="-.265888 0 0.02" rgba="0.85 0.2 0.2 1.0" /><geom name="Fleet1Tenth_0_number" type="cylinder" contype="0" conaffinity="0" size=".01984 .03" pos=".12 0 .05" rgba="0.1 0.1 0.1 1.0" /><geom name="Fleet1Tenth_0_camera" type="box" contype="0" conaffinity="0" size=".012 .06 0.02" pos=".18 0 .08" /><geom name="Fleet1Tenth_0_camera_holder" type="box" contype="0" conaffinity="0" size=".012 .008 .02" pos=".18 0 .04" /><geom name="Fleet1Tenth_0_circuits" type="box" contype="0" conaffinity="0" size=".08 .06 .03" pos="-.05 0 .05" rgba="0.85 0.2 0.2 1.0" /><geom name="Fleet1Tenth_0_antennal" type="box" contype="0" conaffinity="0" size=".007 .004 .06" pos="-.16 -.01 .105" euler="0.2 0 0" rgba=".1 .1 .1 1.0" /><geom name="Fleet1Tenth_0_antennar" type="box" contype="0" conaffinity="0" size=".007 .004 .06" pos="-.16 .01 .105" euler="-0.2 0 0" rgba=".1 .1 .1 1.0" /><geom name="Fleet1Tenth_0_antenna_holder" type="box" contype="0" conaffinity="0" size=".008 .008 .02" pos="-.16 0 .04" rgba=".1 .1 .1 1.0" /><body name="Fleet1Tenth_0_wheelfl"><joint name="Fleet1Tenth_0_wheelfl_steer" type="hinge" pos="0.16113 .10016 0" limited="true" frictionloss="0.2" damping="0.2" armature="0.001" range="-0.6 0.6" axis="0 0 1" /><joint name="Fleet1Tenth_0_wheelfl" type="hinge" pos="0.16113 .122385 0" axis="0 1 0" frictionloss="0.01" damping="0.00001" armature="0.05" limited="false" /><geom name="Fleet1Tenth_0_wheelfl" type="cylinder" contype="0" conaffinity="0" size=".052388 .022225" pos="0.16113 .122385 0" mass="0.1" material="material_check" euler="1.571 0 0" /></body><body name="Fleet1Tenth_0_wheelrl"><joint name="Fleet1Tenth_0_wheelrl" type="hinge" pos="-0.16113 .122385 0" axis="0 1 0" frictionloss="0.01" damping="0.00001" armature="0.05" limited="false" /><geom name="Fleet1Tenth_0_wheelrl" type="cylinder" contype="0" conaffinity="0" size=".052388 .022225" pos="-0.16113 .122385 0" mass="0.1" material="material_check" euler="1.571 0 0" /></body><body name="Fleet1Tenth_0_wheelfr"><joint name="Fleet1Tenth_0_wheelfr_steer" type="hinge" pos="0.16113 -.10016 0" limited="true" frictionloss="0.2" damping="0.2" armature="0.001" range="-0.6 0.6" axis="0 0 1" /><joint name="Fleet1Tenth_0_wheelfr" type="hinge" pos="0.16113 -.122385 0" axis="0 1 0" frictionloss="0.01" damping="0.00001" armature="0.05" limited="false" /><geom name="Fleet1Tenth_0_wheelfr" type="cylinder" contype="0" conaffinity="0" size=".052388 .022225" pos="0.16113 -.122385 0" mass="0.1" material="material_check" euler="1.571 0 0" /></body><body name="Fleet1Tenth_0_wheelrr"><joint name="Fleet1Tenth_0_wheelrr" type="hinge" pos="-0.16113 -.122385 0" axis="0 1 0" frictionloss="0.01" damping="0.00001" armature="0.05" limited="false" /><geom name="Fleet1Tenth_0_wheelrr" type="cylinder" contype="0" conaffinity="0" size=".052388 .022225" pos="-0.16113 -.122385 0" mass="0.1" material="material_check" euler="1.571 0 0" /></body></body><body name="mpcc_0" mocap="true" pos="0 0 1" quat="0.9485664043524404 0 0 0.31657823130133655"><geom name="mpcc_marker0" type="sphere" contype="0" conaffinity="0" size="0.1" pos="0 0 0" rgba="0.2 0.2 0.85 1.0" /></body><body name="mpcc_1" mocap="true" pos="1 0 1" quat="0.9485664043524404 0 0 0.31657823130133655"><geom name="mpcc_marker1" type="sphere" contype="0" conaffinity="0" size="0.1" pos="0 0 0" rgba="0.2 0.2 0.85 1.0" /></body><body name="mpcc_2" mocap="true" pos="2 0 1" quat="0.9485664043524404 0 0 0.31657823130133655"><geom name="mpcc_marker2" type="sphere" contype="0" conaffinity="0" size="0.1" pos="0 0 0" rgba="0.2 0.2 0.85 1.0" /></body><body name="mpcc_3" mocap="true" pos="3 0 1" quat="0.9485664043524404 0 0 0.31657823130133655"><geom name="mpcc_marker3" type="sphere" contype="0" conaffinity="0" size="0.1" pos="0 0 0" rgba="0.2 0.2 0.85 1.0" /></body><body name="mpcc_4" mocap="true" pos="4 0 1" quat="0.9485664043524404 0 0 0.31657823130133655"><geom name="mpcc_marker4" type="sphere" contype="0" conaffinity="0" size="0.1" pos="0 0 0" rgba="0.2 0.2 0.85 1.0" /></body><body name="mpcc_5" mocap="true" pos="5 0 1" quat="0.9485664043524404 0 0 0.31657823130133655"><geom name="mpcc_marker5" type="sphere" contype="0" conaffinity="0" size="0.1" pos="0 0 0" rgba="0.2 0.2 0.85 1.0" /></body><body name="mpcc_6" mocap="true" pos="6 0 1" quat="0.9485664043524404 0 0 0.31657823130133655"><geom name="mpcc_marker6" type="sphere" contype="0" conaffinity="0" size="0.1" pos="0 0 0" rgba="0.2 0.2 0.85 1.0" /></body><body name="mpcc_7" mocap="true" pos="7 0 1" quat="0.9485664043524404 0 0 0.31657823130133655"><geom name="mpcc_marker7" type="sphere" contype="0" conaffinity="0" size="0.1" pos="0 0 0" rgba="0.2 0.2 0.85 1.0" /></body><body name="mpcc_8" mocap="true" pos="8 0 1" quat="0.9485664043524404 0 0 0.31657823130133655"><geom name="mpcc_marker8" type="sphere" contype="0" conaffinity="0" size="0.1" pos="0 0 0" rgba="0.2 0.2 0.85 1.0" /></body><body name="mpcc_9" mocap="true" pos="9 0 1" quat="0.9485664043524404 0 0 0.31657823130133655"><geom name="mpcc_marker9" type="sphere" contype="0" conaffinity="0" size="0.1" pos="0 0 0" rgba="0.2 0.2 0.85 1.0" /></body><body name="mpcc_10" mocap="true" pos="10 0 1" quat="0.9485664043524404 0 0 0.31657823130133655"><geom name="mpcc_marker10" type="sphere" contype="0" conaffinity="0" size="0.1" pos="0 0 0" rgba="0.2 0.2 0.85 1.0" /></body><body name="mpcc_11" mocap="true" pos="11 0 1" quat="0.9485664043524404 0 0 0.31657823130133655"><geom name="mpcc_marker11" type="sphere" contype="0" conaffinity="0" size="0.1" pos="0 0 0" rgba="0.2 0.2 0.85 1.0" /></body><body name="mpcc_12" mocap="true" pos="12 0 1" quat="0.9485664043524404 0 0 0.31657823130133655"><geom name="mpcc_marker12" type="sphere" contype="0" conaffinity="0" size="0.1" pos="0 0 0" rgba="0.2 0.2 0.85 1.0" /></body><body name="mpcc_13" mocap="true" pos="13 0 1" quat="0.9485664043524404 0 0 0.31657823130133655"><geom name="mpcc_marker13" type="sphere" contype="0" conaffinity="0" size="0.1" pos="0 0 0" rgba="0.2 0.2 0.85 1.0" /></body><body name="mpcc_14" mocap="true" pos="14 0 1" quat="0.9485664043524404 0 0 0.31657823130133655"><geom name="mpcc_marker14" type="sphere" contype="0" conaffinity="0" size="0.1" pos="0 0 0" rgba="0.2 0.2 0.85 1.0" /></body><body name="ref_trajectory_body0" mocap="true" pos="0 0 0"><geom type="sphere" size="0.05" contype="0" conaffinity="0" rgba="0.1 0.85 0.1 1.0" pos="0.012489401322906414 -0.015289092129418464 0" /><geom type="sphere" size="0.05" contype="0" conaffinity="0" rgba="0.1 0.85 0.1 1.0" pos="0.12514447297696857 0.13082323033146637 0" /><geom type="sphere" size="0.05" contype="0" conaffinity="0" rgba="0.1 0.85 0.1 1.0" pos="0.2465225503879269 0.26474203210463887 0" /><geom type="sphere" size="0.05" contype="0" conaffinity="0" rgba="0.1 0.85 0.1 1.0" pos="0.3743542592642528 0.3905134194399542 0" /><geom type="sphere" size="0.05" contype="0" conaffinity="0" rgba="0.1 0.85 0.1 1.0" pos="0.5062512727380947 0.5118132749040044 0" /><geom type="sphere" size="0.05" contype="0" conaffinity="0" rgba="0.1 0.85 0.1 1.0" pos="0.6397123737636184 0.6319551971517495 0" /><geom type="sphere" size="0.05" contype="0" conaffinity="0" rgba="0.1 0.85 0.1 1.0" pos="0.7721593167933267 0.7539374679957224 0" /><geom type="sphere" size="0.05" contype="0" conaffinity="0" rgba="0.1 0.85 0.1 1.0" pos="0.900760780199952 0.8802113949126782 0" /><geom type="sphere" size="0.05" contype="0" conaffinity="0" rgba="0.1 0.85 0.1 1.0" pos="1.01658267163643 1.004878650074241 0" /><geom type="sphere" size="0.05" contype="0" conaffinity="0" rgba="0.1 0.85 0.1 1.0" pos="1.3232943264574544 1.457167340728455 0" /><geom type="sphere" size="0.05" contype="0" conaffinity="0" rgba="0.1 0.85 0.1 1.0" pos="1.4947523865271044 2.1322707702967683 0" /><geom type="sphere" size="0.05" contype="0" conaffinity="0" rgba="0.1 0.85 0.1 1.0" pos="1.3499301541919349 2.803560625446934 0" /><geom type="sphere" size="0.05" contype="0" conaffinity="0" rgba="0.1 0.85 0.1 1.0" pos="0.890376093963527 3.32650300005162 0" /><geom type="sphere" size="0.05" contype="0" conaffinity="0" rgba="0.1 0.85 0.1 1.0" pos="0.21946859021991066 3.5961741444857194 0" /><geom type="sphere" size="0.05" contype="0" conaffinity="0" rgba="0.1 0.85 0.1 1.0" pos="-0.4800041265741217 3.549628550360183 0" /><geom type="sphere" size="0.05" contype="0" conaffinity="0" rgba="0.1 0.85 0.1 1.0" pos="-1.0469899962597797 3.187815088668652 0" /><geom type="sphere" size="0.05" contype="0" conaffinity="0" rgba="0.1 0.85 0.1 1.0" pos="-1.3969016158350347 2.587749661254506 0" /><geom type="sphere" size="0.05" contype="0" conaffinity="0" rgba="0.1 0.85 0.1 1.0" pos="-1.5247203134475336 1.8907119794742944 0" /><geom type="sphere" size="0.05" contype="0" conaffinity="0" rgba="0.1 0.85 0.1 1.0" pos="-1.5147337228221722 1.1988457805826513 0" /><geom type="sphere" size="0.05" contype="0" conaffinity="0" rgba="0.1 0.85 0.1 1.0" pos="-1.4913894516156536 0.5117896258374437 0" /><geom type="sphere" size="0.05" contype="0" conaffinity="0" rgba="0.1 0.85 0.1 1.0" pos="-1.491927635651623 -0.17507666641054184 0" /><geom type="sphere" size="0.05" contype="0" conaffinity="0" rgba="0.1 0.85 0.1 1.0" pos="-1.5001023031557736 -0.8632293186461456 0" /><geom type="sphere" size="0.05" contype="0" conaffinity="0" rgba="0.1 0.85 0.1 1.0" pos="-1.5044374204608633 -1.5529841762418863 0" /><geom type="sphere" size="0.05" contype="0" conaffinity="0" rgba="0.1 0.85 0.1 1.0" pos="-1.5016741242652356 -2.243642971939696 0" /><geom type="sphere" size="0.05" contype="0" conaffinity="0" rgba="0.1 0.85 0.1 1.0" pos="-1.4967766749420337 -2.933495613773759 0" /><geom type="sphere" size="0.05" contype="0" conaffinity="0" rgba="0.1 0.85 0.1 1.0" pos="-1.5029336313808335 -3.6198205794756 0" /></body><body name="ref_trajectory_body1" mocap="true" pos="0 0 0"><geom type="sphere" size="0.05" contype="0" conaffinity="0" rgba="0.8 0.5 0.1 1.0" pos="-1.519686713349748 -3.6152434103715603 0" /><geom type="sphere" size="0.05" contype="0" conaffinity="0" rgba="0.8 0.5 0.1 1.0" pos="-1.4925495202920176 -2.9826610607360795 0" /><geom type="sphere" size="0.05" contype="0" conaffinity="0" rgba="0.8 0.5 0.1 1.0" pos="-1.518482264293035 -2.329551490370608 0" /><geom type="sphere" size="0.05" contype="0" conaffinity="0" rgba="0.8 0.5 0.1 1.0" pos="-1.450373188603035 -1.7869721430974739 0" /><geom type="sphere" size="0.05" contype="0" conaffinity="0" rgba="0.8 0.5 0.1 1.0" pos="-1.261410438490629 -1.332393000638995 0" /><geom type="sphere" size="0.05" contype="0" conaffinity="0" rgba="0.8 0.5 0.1 1.0" pos="-0.9272525652890996 -0.9000416665821576 0" /><geom type="sphere" size="0.05" contype="0" conaffinity="0" rgba="0.8 0.5 0.1 1.0" pos="-0.4459150937656665 -0.45705915670016756 0" /><geom type="sphere" size="0.05" contype="0" conaffinity="0" rgba="0.8 0.5 0.1 1.0" pos="-0.02204079699065847 0.011020827524431896 0" /></body></worldbody><contact><pair geom1="Fleet1Tenth_0_wheelfl" geom2="roundabout" condim="6" friction="2.5 2.5 .009 .0001 .0001" /><pair geom1="Fleet1Tenth_0_wheelfr" geom2="roundabout" condim="6" friction="2.5 2.5 .009 .0001 .0001" /><pair geom1="Fleet1Tenth_0_wheelrl" geom2="roundabout" condim="6" friction="2.5 2.5 .009 .0001 .0001" /><pair geom1="Fleet1Tenth_0_wheelrr" geom2="roundabout" condim="6" friction="2.5 2.5 .009 .0001 .0001" /><exclude name="car_marker_exc0" body1="Fleet1Tenth_0" body2="mpcc_0" /><exclude name="car_marker_exc1" body1="Fleet1Tenth_0" body2="mpcc_1" /><exclude name="car_marker_exc2" body1="Fleet1Tenth_0" body2="mpcc_2" /><exclude name="car_marker_exc3" body1="Fleet1Tenth_0" body2="mpcc_3" /><exclude name="car_marker_exc4" body1="Fleet1Tenth_0" body2="mpcc_4" /><exclude name="car_marker_exc5" body1="Fleet1Tenth_0" body2="mpcc_5" /><exclude name="car_marker_exc6" body1="Fleet1Tenth_0" body2="mpcc_6" /><exclude name="car_marker_exc7" body1="Fleet1Tenth_0" body2="mpcc_7" /><exclude name="car_marker_exc8" body1="Fleet1Tenth_0" body2="mpcc_8" /><exclude name="car_marker_exc9" body1="Fleet1Tenth_0" body2="mpcc_9" /><exclude name="car_marker_exc10" body1="Fleet1Tenth_0" body2="mpcc_10" /><exclude name="car_marker_exc11" body1="Fleet1Tenth_0" body2="mpcc_11" /><exclude name="car_marker_exc12" body1="Fleet1Tenth_0" body2="mpcc_12" /><exclude name="car_marker_exc13" body1="Fleet1Tenth_0" body2="mpcc_13" /><exclude name="car_marker_exc14" body1="Fleet1Tenth_0" body2="mpcc_14" /><exclude name="marker_exclude0" body1="Fleet1Tenth_0" body2="ref_trajectory_body0" /><exclude name="marker_exclude1" body1="Fleet1Tenth_0" body2="ref_trajectory_body1" /></contact><actuator><motor name="Fleet1Tenth_0_wheelfl_actr" joint="Fleet1Tenth_0_wheelfl" /><motor name="Fleet1Tenth_0_wheelfr_actr" joint="Fleet1Tenth_0_wheelfr" /><motor name="Fleet1Tenth_0_wheelrl_actr" joint="Fleet1Tenth_0_wheelrl" /><motor name="Fleet1Tenth_0_wheelrr_actr" joint="Fleet1Tenth_0_wheelrr" /><position forcelimited="true" forcerange="-5 5" name="Fleet1Tenth_0_wheelfl_actr_steer" joint="Fleet1Tenth_0_wheelfl_steer" kp="15" /><position forcelimited="true" forcerange="-5 5" name="Fleet1Tenth_0_wheelfr_actr_steer" joint="Fleet1Tenth_0_wheelfr_steer" kp="15" /></actuator><sensor><gyro site="Fleet1Tenth_0_cog" name="Fleet1Tenth_0_gyro" /><velocimeter site="Fleet1Tenth_0_cog" name="Fleet1Tenth_0_velocimeter" /><framepos objtype="site" objname="Fleet1Tenth_0_cog" name="Fleet1Tenth_0_posimeter" /><framequat objtype="site" objname="Fleet1Tenth_0_cog" name="Fleet1Tenth_0_orimeter" /><accelerometer site="Fleet1Tenth_0_cog" name="Fleet1Tenth_0_accelerometer" /></sensor><option><flag contact="enable" /></option></mujoco>