<mujoco><include file="scene_without_walls.xml" /><worldbody><body name="Fleet1Tenth_0" pos="0.1 0.0 .052388" quat="0.9238795325112867 0 0 0.3826834323650898"><inertial pos="0 0 0" diaginertia=".05 .05 .08" mass="3.0" /><joint name="Fleet1Tenth_0" type="free" /><site name="Fleet1Tenth_0_cog" pos="0 0 0" /><geom name="Fleet1Tenth_0_chassis_b" type="box" contype="0" conaffinity="0" size=".10113 .1016 .02" pos="-.06 0 0" rgba="0.85 0.2 0.2 1.0" /><geom name="Fleet1Tenth_0_chassis_f" type="box" contype="0" conaffinity="0" size=".06 .07 .02" pos=".10113 0 0" rgba="0.85 0.2 0.2 1.0" /><geom name="Fleet1Tenth_0_front" type="box" contype="0" conaffinity="0" size=".052388 .02 .02" pos=".2135 0 0" rgba="0.85 0.2 0.2 1.0" /><geom name="Fleet1Tenth_0_back" type="box" contype="0" conaffinity="0" size=".052388 .02 .02" pos="-.2135 0 0" rgba="0.85 0.2 0.2 1.0" /><geom name="Fleet1Tenth_0_front_bumper" type="box" contype="0" conaffinity="0" size=".005 .09 .02" pos=".265888 0 0.02" rgba="0.85 0.2 0.2 1.0" /><geom name="Fleet1Tenth_0_back_bumper" type="box" contype="0" conaffinity="0" size=".005 .08 .02" pos="-.265888 0 0.02" rgba="0.85 0.2 0.2 1.0" /><geom name="Fleet1Tenth_0_number" type="cylinder" contype="0" conaffinity="0" size=".01984 .03" pos=".12 0 .05" rgba="0.1 0.1 0.1 1.0" /><geom name="Fleet1Tenth_0_camera" type="box" contype="0" conaffinity="0" size=".012 .06 0.02" pos=".18 0 .08" /><geom name="Fleet1Tenth_0_camera_holder" type="box" contype="0" conaffinity="0" size=".012 .008 .02" pos=".18 0 .04" /><geom name="Fleet1Tenth_0_circuits" type="box" contype="0" conaffinity="0" size=".08 .06 .03" pos="-.05 0 .05" rgba="0.85 0.2 0.2 1.0" /><geom name="Fleet1Tenth_0_antennal" type="box" contype="0" conaffinity="0" size=".007 .004 .06" pos="-.16 -.01 .105" euler="0.2 0 0" rgba=".1 .1 .1 1.0" /><geom name="Fleet1Tenth_0_antennar" type="box" contype="0" conaffinity="0" size=".007 .004 .06" pos="-.16 .01 .105" euler="-0.2 0 0" rgba=".1 .1 .1 1.0" /><geom name="Fleet1Tenth_0_antenna_holder" type="box" contype="0" conaffinity="0" size=".008 .008 .02" pos="-.16 0 .04" rgba=".1 .1 .1 1.0" /><body name="Fleet1Tenth_0_wheelfl"><joint name="Fleet1Tenth_0_wheelfl_steer" type="hinge" pos="0.16113 .10016 0" limited="true" frictionloss="0.2" damping="0.2" armature="0.001" range="-0.6 0.6" axis="0 0 1" /><joint name="Fleet1Tenth_0_wheelfl" type="hinge" pos="0.16113 .122385 0" axis="0 1 0" frictionloss="0.01" damping="0.00001" armature="0.05" limited="false" /><geom name="Fleet1Tenth_0_wheelfl" type="cylinder" contype="0" conaffinity="0" size=".052388 .022225" pos="0.16113 .122385 0" mass="0.1" material="material_check" euler="1.571 0 0" /></body><body name="Fleet1Tenth_0_wheelrl"><joint name="Fleet1Tenth_0_wheelrl" type="hinge" pos="-0.16113 .122385 0" axis="0 1 0" frictionloss="0.01" damping="0.00001" armature="0.05" limited="false" /><geom name="Fleet1Tenth_0_wheelrl" type="cylinder" contype="0" conaffinity="0" size=".052388 .022225" pos="-0.16113 .122385 0" mass="0.1" material="material_check" euler="1.571 0 0" /></body><body name="Fleet1Tenth_0_wheelfr"><joint name="Fleet1Tenth_0_wheelfr_steer" type="hinge" pos="0.16113 -.10016 0" limited="true" frictionloss="0.2" damping="0.2" armature="0.001" range="-0.6 0.6" axis="0 0 1" /><joint name="Fleet1Tenth_0_wheelfr" type="hinge" pos="0.16113 -.122385 0" axis="0 1 0" frictionloss="0.01" damping="0.00001" armature="0.05" limited="false" /><geom name="Fleet1Tenth_0_wheelfr" type="cylinder" contype="0" conaffinity="0" size=".052388 .022225" pos="0.16113 -.122385 0" mass="0.1" material="material_check" euler="1.571 0 0" /></body><body name="Fleet1Tenth_0_wheelrr"><joint name="Fleet1Tenth_0_wheelrr" type="hinge" pos="-0.16113 -.122385 0" axis="0 1 0" frictionloss="0.01" damping="0.00001" armature="0.05" limited="false" /><geom name="Fleet1Tenth_0_wheelrr" type="cylinder" contype="0" conaffinity="0" size=".052388 .022225" pos="-0.16113 -.122385 0" mass="0.1" material="material_check" euler="1.571 0 0" /></body></body><body name="mpcc_0" mocap="true" pos="0 0 1" quat="0.9485664043524404 0 0 0.31657823130133655"><geom name="mpcc_marker0" type="sphere" contype="0" conaffinity="0" size="0.1" pos="0 0 0" rgba="0.2 0.2 0.85 1.0" /></body><body name="mpcc_1" mocap="true" pos="1 0 1" quat="0.9485664043524404 0 0 0.31657823130133655"><geom name="mpcc_marker1" type="sphere" contype="0" conaffinity="0" size="0.1" pos="0 0 0" rgba="0.2 0.2 0.85 1.0" /></body><body name="mpcc_2" mocap="true" pos="2 0 1" quat="0.9485664043524404 0 0 0.31657823130133655"><geom name="mpcc_marker2" type="sphere" contype="0" conaffinity="0" size="0.1" pos="0 0 0" rgba="0.2 0.2 0.85 1.0" /></body><body name="mpcc_3" mocap="true" pos="3 0 1" quat="0.9485664043524404 0 0 0.31657823130133655"><geom name="mpcc_marker3" type="sphere" contype="0" conaffinity="0" size="0.1" pos="0 0 0" rgba="0.2 0.2 0.85 1.0" /></body><body name="mpcc_4" mocap="true" pos="4 0 1" quat="0.9485664043524404 0 0 0.31657823130133655"><geom name="mpcc_marker4" type="sphere" contype="0" conaffinity="0" size="0.1" pos="0 0 0" rgba="0.2 0.2 0.85 1.0" /></body><body name="mpcc_5" mocap="true" pos="5 0 1" quat="0.9485664043524404 0 0 0.31657823130133655"><geom name="mpcc_marker5" type="sphere" contype="0" conaffinity="0" size="0.1" pos="0 0 0" rgba="0.2 0.2 0.85 1.0" /></body><body name="mpcc_6" mocap="true" pos="6 0 1" quat="0.9485664043524404 0 0 0.31657823130133655"><geom name="mpcc_marker6" type="sphere" contype="0" conaffinity="0" size="0.1" pos="0 0 0" rgba="0.2 0.2 0.85 1.0" /></body><body name="mpcc_7" mocap="true" pos="7 0 1" quat="0.9485664043524404 0 0 0.31657823130133655"><geom name="mpcc_marker7" type="sphere" contype="0" conaffinity="0" size="0.1" pos="0 0 0" rgba="0.2 0.2 0.85 1.0" /></body><body name="mpcc_8" mocap="true" pos="8 0 1" quat="0.9485664043524404 0 0 0.31657823130133655"><geom name="mpcc_marker8" type="sphere" contype="0" conaffinity="0" size="0.1" pos="0 0 0" rgba="0.2 0.2 0.85 1.0" /></body><body name="mpcc_9" mocap="true" pos="9 0 1" quat="0.9485664043524404 0 0 0.31657823130133655"><geom name="mpcc_marker9" type="sphere" contype="0" conaffinity="0" size="0.1" pos="0 0 0" rgba="0.2 0.2 0.85 1.0" /></body><body name="mpcc_10" mocap="true" pos="10 0 1" quat="0.9485664043524404 0 0 0.31657823130133655"><geom name="mpcc_marker10" type="sphere" contype="0" conaffinity="0" size="0.1" pos="0 0 0" rgba="0.2 0.2 0.85 1.0" /></body><body name="mpcc_11" mocap="true" pos="11 0 1" quat="0.9485664043524404 0 0 0.31657823130133655"><geom name="mpcc_marker11" type="sphere" contype="0" conaffinity="0" size="0.1" pos="0 0 0" rgba="0.2 0.2 0.85 1.0" /></body><body name="mpcc_12" mocap="true" pos="12 0 1" quat="0.9485664043524404 0 0 0.31657823130133655"><geom name="mpcc_marker12" type="sphere" contype="0" conaffinity="0" size="0.1" pos="0 0 0" rgba="0.2 0.2 0.85 1.0" /></body><body name="mpcc_13" mocap="true" pos="13 0 1" quat="0.9485664043524404 0 0 0.31657823130133655"><geom name="mpcc_marker13" type="sphere" contype="0" conaffinity="0" size="0.1" pos="0 0 0" rgba="0.2 0.2 0.85 1.0" /></body><body name="mpcc_14" mocap="true" pos="14 0 1" quat="0.9485664043524404 0 0 0.31657823130133655"><geom name="mpcc_marker14" type="sphere" contype="0" conaffinity="0" size="0.1" pos="0 0 0" rgba="0.2 0.2 0.85 1.0" /></body><body name="ref_trajectory_body0" mocap="true" pos="0 0 0"><geom type="sphere" size="0.05" contype="0" conaffinity="0" rgba="0.1 0.85 0.1 1.0" pos="0.009803247383709569 -0.013027388308085353 0" /><geom type="sphere" size="0.05" contype="0" conaffinity="0" rgba="0.1 0.85 0.1 1.0" pos="0.12345771086795755 0.1317697379358597 0" /><geom type="sphere" size="0.05" contype="0" conaffinity="0" rgba="0.1 0.85 0.1 1.0" pos="0.2455579669023948 0.26572729147853236 0" /><geom type="sphere" size="0.05" contype="0" conaffinity="0" rgba="0.1 0.85 0.1 1.0" pos="0.3740660085657183 0.39224511091316194 0" /><geom type="sphere" size="0.05" contype="0" conaffinity="0" rgba="0.1 0.85 0.1 1.0" pos="0.5060607304083443 0.5135464793996454 0" /><geom type="sphere" size="0.05" contype="0" conaffinity="0" rgba="0.1 0.85 0.1 1.0" pos="0.6410159219698032 0.6353047683467805 0" /><geom type="sphere" size="0.05" contype="0" conaffinity="0" rgba="0.1 0.85 0.1 1.0" pos="0.7697684266107107 0.751072838461986 0" /><geom type="sphere" size="0.05" contype="0" conaffinity="0" rgba="0.1 0.85 0.1 1.0" pos="0.9098397452151558 0.8921343732955905 0" /><geom type="sphere" size="0.05" contype="0" conaffinity="0" rgba="0.1 0.85 0.1 1.0" pos="0.9981179802440505 0.9753570563172335 0" /><geom type="sphere" size="0.05" contype="0" conaffinity="0" rgba="0.1 0.85 0.1 1.0" pos="1.2990909324467355 1.4257014291490608 0" /><geom type="sphere" size="0.05" contype="0" conaffinity="0" rgba="0.1 0.85 0.1 1.0" pos="1.4948722462243673 2.13022938369077 0" /><geom type="sphere" size="0.05" contype="0" conaffinity="0" rgba="0.1 0.85 0.1 1.0" pos="1.35067496572152 2.8182685859968752 0" /><geom type="sphere" size="0.05" contype="0" conaffinity="0" rgba="0.1 0.85 0.1 1.0" pos="0.8970508825070566 3.3436385662995534 0" /><geom type="sphere" size="0.05" contype="0" conaffinity="0" rgba="0.1 0.85 0.1 1.0" pos="0.2214046420351595 3.5864449656123614 0" /><geom type="sphere" size="0.05" contype="0" conaffinity="0" rgba="0.1 0.85 0.1 1.0" pos="-0.48937962054467987 3.5213989334748828 0" /><geom type="sphere" size="0.05" contype="0" conaffinity="0" rgba="0.1 0.85 0.1 1.0" pos="-1.0546860857236788 3.178423292254422 0" /><geom type="sphere" size="0.05" contype="0" conaffinity="0" rgba="0.1 0.85 0.1 1.0" pos="-1.3895794192066773 2.6134638224135323 0" /><geom type="sphere" size="0.05" contype="0" conaffinity="0" rgba="0.1 0.85 0.1 1.0" pos="-1.5114165014298093 1.9162219173839066 0" /><geom type="sphere" size="0.05" contype="0" conaffinity="0" rgba="0.1 0.85 0.1 1.0" pos="-1.5183860317221642 1.1899267883616524 0" /><geom type="sphere" size="0.05" contype="0" conaffinity="0" rgba="0.1 0.85 0.1 1.0" pos="-1.5009851788439443 0.48636330148478946 0" /><geom type="sphere" size="0.05" contype="0" conaffinity="0" rgba="0.1 0.85 0.1 1.0" pos="-1.494105769830272 -0.18460760645187163 0" /><geom type="sphere" size="0.05" contype="0" conaffinity="0" rgba="0.1 0.85 0.1 1.0" pos="-1.4966798224387066 -0.8520375325749482 0" /><geom type="sphere" size="0.05" contype="0" conaffinity="0" rgba="0.1 0.85 0.1 1.0" pos="-1.5005068446932344 -1.5378392246048185 0" /><geom type="sphere" size="0.05" contype="0" conaffinity="0" rgba="0.1 0.85 0.1 1.0" pos="-1.501781838186174 -2.243063048169531 0" /><geom type="sphere" size="0.05" contype="0" conaffinity="0" rgba="0.1 0.85 0.1 1.0" pos="-1.500254640529709 -2.9483905359380858 0" /><geom type="sphere" size="0.05" contype="0" conaffinity="0" rgba="0.1 0.85 0.1 1.0" pos="-1.4995512100783748 -3.613889489595155 0" /></body><body name="ref_trajectory_body1" mocap="true" pos="0 0 0"><geom type="sphere" size="0.05" contype="0" conaffinity="0" rgba="0.8 0.5 0.1 1.0" pos="-1.5198882502019904 -3.6094689793718215 0" /><geom type="sphere" size="0.05" contype="0" conaffinity="0" rgba="0.8 0.5 0.1 1.0" pos="-1.4890253024835636 -3.098614337195049 0" /><geom type="sphere" size="0.05" contype="0" conaffinity="0" rgba="0.8 0.5 0.1 1.0" pos="-1.5154074614409734 -2.5566524717241057 0" /><geom type="sphere" size="0.05" contype="0" conaffinity="0" rgba="0.8 0.5 0.1 1.0" pos="-1.4810257564052036 -1.9652261238569202 0" /><geom type="sphere" size="0.05" contype="0" conaffinity="0" rgba="0.8 0.5 0.1 1.0" pos="-1.157255623593378 -1.18464041426045 0" /><geom type="sphere" size="0.05" contype="0" conaffinity="0" rgba="0.8 0.5 0.1 1.0" pos="-0.7635552743075218 -0.7418735356898692 0" /><geom type="sphere" size="0.05" contype="0" conaffinity="0" rgba="0.8 0.5 0.1 1.0" pos="-0.36227694390450005 -0.3773017254182568 0" /><geom type="sphere" size="0.05" contype="0" conaffinity="0" rgba="0.8 0.5 0.1 1.0" pos="-0.02168638177276509 0.005592804999931236 0" /></body></worldbody><contact><pair geom1="Fleet1Tenth_0_wheelfl" geom2="roundabout" condim="6" friction="2.5 2.5 .009 .0001 .0001" /><pair geom1="Fleet1Tenth_0_wheelfr" geom2="roundabout" condim="6" friction="2.5 2.5 .009 .0001 .0001" /><pair geom1="Fleet1Tenth_0_wheelrl" geom2="roundabout" condim="6" friction="2.5 2.5 .009 .0001 .0001" /><pair geom1="Fleet1Tenth_0_wheelrr" geom2="roundabout" condim="6" friction="2.5 2.5 .009 .0001 .0001" /><exclude name="car_marker_exc0" body1="Fleet1Tenth_0" body2="mpcc_0" /><exclude name="car_marker_exc1" body1="Fleet1Tenth_0" body2="mpcc_1" /><exclude name="car_marker_exc2" body1="Fleet1Tenth_0" body2="mpcc_2" /><exclude name="car_marker_exc3" body1="Fleet1Tenth_0" body2="mpcc_3" /><exclude name="car_marker_exc4" body1="Fleet1Tenth_0" body2="mpcc_4" /><exclude name="car_marker_exc5" body1="Fleet1Tenth_0" body2="mpcc_5" /><exclude name="car_marker_exc6" body1="Fleet1Tenth_0" body2="mpcc_6" /><exclude name="car_marker_exc7" body1="Fleet1Tenth_0" body2="mpcc_7" /><exclude name="car_marker_exc8" body1="Fleet1Tenth_0" body2="mpcc_8" /><exclude name="car_marker_exc9" body1="Fleet1Tenth_0" body2="mpcc_9" /><exclude name="car_marker_exc10" body1="Fleet1Tenth_0" body2="mpcc_10" /><exclude name="car_marker_exc11" body1="Fleet1Tenth_0" body2="mpcc_11" /><exclude name="car_marker_exc12" body1="Fleet1Tenth_0" body2="mpcc_12" /><exclude name="car_marker_exc13" body1="Fleet1Tenth_0" body2="mpcc_13" /><exclude name="car_marker_exc14" body1="Fleet1Tenth_0" body2="mpcc_14" /><exclude name="marker_exclude0" body1="Fleet1Tenth_0" body2="ref_trajectory_body0" /><exclude name="marker_exclude1" body1="Fleet1Tenth_0" body2="ref_trajectory_body1" /></contact><actuator><motor name="Fleet1Tenth_0_wheelfl_actr" joint="Fleet1Tenth_0_wheelfl" /><motor name="Fleet1Tenth_0_wheelfr_actr" joint="Fleet1Tenth_0_wheelfr" /><motor name="Fleet1Tenth_0_wheelrl_actr" joint="Fleet1Tenth_0_wheelrl" /><motor name="Fleet1Tenth_0_wheelrr_actr" joint="Fleet1Tenth_0_wheelrr" /><position forcelimited="true" forcerange="-5 5" name="Fleet1Tenth_0_wheelfl_actr_steer" joint="Fleet1Tenth_0_wheelfl_steer" kp="15" /><position forcelimited="true" forcerange="-5 5" name="Fleet1Tenth_0_wheelfr_actr_steer" joint="Fleet1Tenth_0_wheelfr_steer" kp="15" /></actuator><sensor><gyro site="Fleet1Tenth_0_cog" name="Fleet1Tenth_0_gyro" /><velocimeter site="Fleet1Tenth_0_cog" name="Fleet1Tenth_0_velocimeter" /><framepos objtype="site" objname="Fleet1Tenth_0_cog" name="Fleet1Tenth_0_posimeter" /><framequat objtype="site" objname="Fleet1Tenth_0_cog" name="Fleet1Tenth_0_orimeter" /><accelerometer site="Fleet1Tenth_0_cog" name="Fleet1Tenth_0_accelerometer" /></sensor><option><flag contact="enable" /></option></mujoco>