<mujoco><include file="scene_without_walls.xml" /><worldbody><body name="Fleet1Tenth_0" pos="0.1 0.0 .052388" quat="0.9238795325112867 0 0 0.3826834323650898"><inertial pos="0 0 0" diaginertia=".05 .05 .08" mass="3.0" /><joint name="Fleet1Tenth_0" type="free" /><site name="Fleet1Tenth_0_cog" pos="0 0 0" /><geom name="Fleet1Tenth_0_chassis_b" type="box" contype="0" conaffinity="0" size=".10113 .1016 .02" pos="-.06 0 0" rgba="0.85 0.2 0.2 1.0" /><geom name="Fleet1Tenth_0_chassis_f" type="box" contype="0" conaffinity="0" size=".06 .07 .02" pos=".10113 0 0" rgba="0.85 0.2 0.2 1.0" /><geom name="Fleet1Tenth_0_front" type="box" contype="0" conaffinity="0" size=".052388 .02 .02" pos=".2135 0 0" rgba="0.85 0.2 0.2 1.0" /><geom name="Fleet1Tenth_0_back" type="box" contype="0" conaffinity="0" size=".052388 .02 .02" pos="-.2135 0 0" rgba="0.85 0.2 0.2 1.0" /><geom name="Fleet1Tenth_0_front_bumper" type="box" contype="0" conaffinity="0" size=".005 .09 .02" pos=".265888 0 0.02" rgba="0.85 0.2 0.2 1.0" /><geom name="Fleet1Tenth_0_back_bumper" type="box" contype="0" conaffinity="0" size=".005 .08 .02" pos="-.265888 0 0.02" rgba="0.85 0.2 0.2 1.0" /><geom name="Fleet1Tenth_0_number" type="cylinder" contype="0" conaffinity="0" size=".01984 .03" pos=".12 0 .05" rgba="0.1 0.1 0.1 1.0" /><geom name="Fleet1Tenth_0_camera" type="box" contype="0" conaffinity="0" size=".012 .06 0.02" pos=".18 0 .08" /><geom name="Fleet1Tenth_0_camera_holder" type="box" contype="0" conaffinity="0" size=".012 .008 .02" pos=".18 0 .04" /><geom name="Fleet1Tenth_0_circuits" type="box" contype="0" conaffinity="0" size=".08 .06 .03" pos="-.05 0 .05" rgba="0.85 0.2 0.2 1.0" /><geom name="Fleet1Tenth_0_antennal" type="box" contype="0" conaffinity="0" size=".007 .004 .06" pos="-.16 -.01 .105" euler="0.2 0 0" rgba=".1 .1 .1 1.0" /><geom name="Fleet1Tenth_0_antennar" type="box" contype="0" conaffinity="0" size=".007 .004 .06" pos="-.16 .01 .105" euler="-0.2 0 0" rgba=".1 .1 .1 1.0" /><geom name="Fleet1Tenth_0_antenna_holder" type="box" contype="0" conaffinity="0" size=".008 .008 .02" pos="-.16 0 .04" rgba=".1 .1 .1 1.0" /><body name="Fleet1Tenth_0_wheelfl"><joint name="Fleet1Tenth_0_wheelfl_steer" type="hinge" pos="0.16113 .10016 0" limited="true" frictionloss="0.2" damping="0.2" armature="0.001" range="-0.6 0.6" axis="0 0 1" /><joint name="Fleet1Tenth_0_wheelfl" type="hinge" pos="0.16113 .122385 0" axis="0 1 0" frictionloss="0.01" damping="0.00001" armature="0.05" limited="false" /><geom name="Fleet1Tenth_0_wheelfl" type="cylinder" contype="0" conaffinity="0" size=".052388 .022225" pos="0.16113 .122385 0" mass="0.1" material="material_check" euler="1.571 0 0" /></body><body name="Fleet1Tenth_0_wheelrl"><joint name="Fleet1Tenth_0_wheelrl" type="hinge" pos="-0.16113 .122385 0" axis="0 1 0" frictionloss="0.01" damping="0.00001" armature="0.05" limited="false" /><geom name="Fleet1Tenth_0_wheelrl" type="cylinder" contype="0" conaffinity="0" size=".052388 .022225" pos="-0.16113 .122385 0" mass="0.1" material="material_check" euler="1.571 0 0" /></body><body name="Fleet1Tenth_0_wheelfr"><joint name="Fleet1Tenth_0_wheelfr_steer" type="hinge" pos="0.16113 -.10016 0" limited="true" frictionloss="0.2" damping="0.2" armature="0.001" range="-0.6 0.6" axis="0 0 1" /><joint name="Fleet1Tenth_0_wheelfr" type="hinge" pos="0.16113 -.122385 0" axis="0 1 0" frictionloss="0.01" damping="0.00001" armature="0.05" limited="false" /><geom name="Fleet1Tenth_0_wheelfr" type="cylinder" contype="0" conaffinity="0" size=".052388 .022225" pos="0.16113 -.122385 0" mass="0.1" material="material_check" euler="1.571 0 0" /></body><body name="Fleet1Tenth_0_wheelrr"><joint name="Fleet1Tenth_0_wheelrr" type="hinge" pos="-0.16113 -.122385 0" axis="0 1 0" frictionloss="0.01" damping="0.00001" armature="0.05" limited="false" /><geom name="Fleet1Tenth_0_wheelrr" type="cylinder" contype="0" conaffinity="0" size=".052388 .022225" pos="-0.16113 -.122385 0" mass="0.1" material="material_check" euler="1.571 0 0" /></body></body><body name="mpcc_0" mocap="true" pos="0 0 1" quat="0.9485664043524404 0 0 0.31657823130133655"><geom name="mpcc_marker0" type="sphere" contype="0" conaffinity="0" size="0.1" pos="0 0 0" rgba="0.2 0.2 0.85 1.0" /></body><body name="mpcc_1" mocap="true" pos="1 0 1" quat="0.9485664043524404 0 0 0.31657823130133655"><geom name="mpcc_marker1" type="sphere" contype="0" conaffinity="0" size="0.1" pos="0 0 0" rgba="0.2 0.2 0.85 1.0" /></body><body name="mpcc_2" mocap="true" pos="2 0 1" quat="0.9485664043524404 0 0 0.31657823130133655"><geom name="mpcc_marker2" type="sphere" contype="0" conaffinity="0" size="0.1" pos="0 0 0" rgba="0.2 0.2 0.85 1.0" /></body><body name="mpcc_3" mocap="true" pos="3 0 1" quat="0.9485664043524404 0 0 0.31657823130133655"><geom name="mpcc_marker3" type="sphere" contype="0" conaffinity="0" size="0.1" pos="0 0 0" rgba="0.2 0.2 0.85 1.0" /></body><body name="mpcc_4" mocap="true" pos="4 0 1" quat="0.9485664043524404 0 0 0.31657823130133655"><geom name="mpcc_marker4" type="sphere" contype="0" conaffinity="0" size="0.1" pos="0 0 0" rgba="0.2 0.2 0.85 1.0" /></body><body name="mpcc_5" mocap="true" pos="5 0 1" quat="0.9485664043524404 0 0 0.31657823130133655"><geom name="mpcc_marker5" type="sphere" contype="0" conaffinity="0" size="0.1" pos="0 0 0" rgba="0.2 0.2 0.85 1.0" /></body><body name="mpcc_6" mocap="true" pos="6 0 1" quat="0.9485664043524404 0 0 0.31657823130133655"><geom name="mpcc_marker6" type="sphere" contype="0" conaffinity="0" size="0.1" pos="0 0 0" rgba="0.2 0.2 0.85 1.0" /></body><body name="mpcc_7" mocap="true" pos="7 0 1" quat="0.9485664043524404 0 0 0.31657823130133655"><geom name="mpcc_marker7" type="sphere" contype="0" conaffinity="0" size="0.1" pos="0 0 0" rgba="0.2 0.2 0.85 1.0" /></body><body name="mpcc_8" mocap="true" pos="8 0 1" quat="0.9485664043524404 0 0 0.31657823130133655"><geom name="mpcc_marker8" type="sphere" contype="0" conaffinity="0" size="0.1" pos="0 0 0" rgba="0.2 0.2 0.85 1.0" /></body><body name="mpcc_9" mocap="true" pos="9 0 1" quat="0.9485664043524404 0 0 0.31657823130133655"><geom name="mpcc_marker9" type="sphere" contype="0" conaffinity="0" size="0.1" pos="0 0 0" rgba="0.2 0.2 0.85 1.0" /></body><body name="mpcc_10" mocap="true" pos="10 0 1" quat="0.9485664043524404 0 0 0.31657823130133655"><geom name="mpcc_marker10" type="sphere" contype="0" conaffinity="0" size="0.1" pos="0 0 0" rgba="0.2 0.2 0.85 1.0" /></body><body name="mpcc_11" mocap="true" pos="11 0 1" quat="0.9485664043524404 0 0 0.31657823130133655"><geom name="mpcc_marker11" type="sphere" contype="0" conaffinity="0" size="0.1" pos="0 0 0" rgba="0.2 0.2 0.85 1.0" /></body><body name="mpcc_12" mocap="true" pos="12 0 1" quat="0.9485664043524404 0 0 0.31657823130133655"><geom name="mpcc_marker12" type="sphere" contype="0" conaffinity="0" size="0.1" pos="0 0 0" rgba="0.2 0.2 0.85 1.0" /></body><body name="mpcc_13" mocap="true" pos="13 0 1" quat="0.9485664043524404 0 0 0.31657823130133655"><geom name="mpcc_marker13" type="sphere" contype="0" conaffinity="0" size="0.1" pos="0 0 0" rgba="0.2 0.2 0.85 1.0" /></body><body name="mpcc_14" mocap="true" pos="14 0 1" quat="0.9485664043524404 0 0 0.31657823130133655"><geom name="mpcc_marker14" type="sphere" contype="0" conaffinity="0" size="0.1" pos="0 0 0" rgba="0.2 0.2 0.85 1.0" /></body><body name="mpcc_15" mocap="true" pos="15 0 1" quat="0.9485664043524404 0 0 0.31657823130133655"><geom name="mpcc_marker15" type="sphere" contype="0" conaffinity="0" size="0.1" pos="0 0 0" rgba="0.2 0.2 0.85 1.0" /></body><body name="mpcc_16" mocap="true" pos="16 0 1" quat="0.9485664043524404 0 0 0.31657823130133655"><geom name="mpcc_marker16" type="sphere" contype="0" conaffinity="0" size="0.1" pos="0 0 0" rgba="0.2 0.2 0.85 1.0" /></body><body name="mpcc_17" mocap="true" pos="17 0 1" quat="0.9485664043524404 0 0 0.31657823130133655"><geom name="mpcc_marker17" type="sphere" contype="0" conaffinity="0" size="0.1" pos="0 0 0" rgba="0.2 0.2 0.85 1.0" /></body><body name="mpcc_18" mocap="true" pos="18 0 1" quat="0.9485664043524404 0 0 0.31657823130133655"><geom name="mpcc_marker18" type="sphere" contype="0" conaffinity="0" size="0.1" pos="0 0 0" rgba="0.2 0.2 0.85 1.0" /></body><body name="mpcc_19" mocap="true" pos="19 0 1" quat="0.9485664043524404 0 0 0.31657823130133655"><geom name="mpcc_marker19" type="sphere" contype="0" conaffinity="0" size="0.1" pos="0 0 0" rgba="0.2 0.2 0.85 1.0" /></body><body name="ref_trajectory_body0" mocap="true" pos="0 0 0"><geom type="sphere" size="0.05" contype="0" conaffinity="0" rgba="0.1 0.85 0.1 1.0" pos="0.02486284043182669 0.009211283651858387 0" /><geom type="sphere" size="0.05" contype="0" conaffinity="0" rgba="0.1 0.85 0.1 1.0" pos="0.7114015824545961 0.689100745879339 0" /><geom type="sphere" size="0.05" contype="0" conaffinity="0" rgba="0.1 0.85 0.1 1.0" pos="1.2010451560582016 1.224944541895591 0" /><geom type="sphere" size="0.05" contype="0" conaffinity="0" rgba="0.1 0.85 0.1 1.0" pos="1.3951444761136762 1.5798482964596963 0" /><geom type="sphere" size="0.05" contype="0" conaffinity="0" rgba="0.1 0.85 0.1 1.0" pos="1.491070834324122 1.9591387653490506 0" /><geom type="sphere" size="0.05" contype="0" conaffinity="0" rgba="0.1 0.85 0.1 1.0" pos="1.4798456092089562 2.3517436181580424 0" /><geom type="sphere" size="0.05" contype="0" conaffinity="0" rgba="0.1 0.85 0.1 1.0" pos="1.3608784274666696 2.736176583828855 0" /><geom type="sphere" size="0.05" contype="0" conaffinity="0" rgba="0.1 0.85 0.1 1.0" pos="1.143975333089819 3.083087395262925 0" /><geom type="sphere" size="0.05" contype="0" conaffinity="0" rgba="0.1 0.85 0.1 1.0" pos="0.8467943002062883 3.3610040486798622 0" /><geom type="sphere" size="0.05" contype="0" conaffinity="0" rgba="0.1 0.85 0.1 1.0" pos="0.4903807464803051 3.5461631137898015 0" /><geom type="sphere" size="0.05" contype="0" conaffinity="0" rgba="0.1 0.85 0.1 1.0" pos="0.09836445509357505 3.6242802230958286 0" /><geom type="sphere" size="0.05" contype="0" conaffinity="0" rgba="0.1 0.85 0.1 1.0" pos="-0.3030415856133284 3.5905526400823775 0" /><geom type="sphere" size="0.05" contype="0" conaffinity="0" rgba="0.1 0.85 0.1 1.0" pos="-0.6850411035183791 3.449659341093554 0" /><geom type="sphere" size="0.05" contype="0" conaffinity="0" rgba="0.1 0.85 0.1 1.0" pos="-1.0163175395866768 3.215729108678408 0" /><geom type="sphere" size="0.05" contype="0" conaffinity="0" rgba="0.1 0.85 0.1 1.0" pos="-1.2677761906612208 2.909919602801481 0" /><geom type="sphere" size="0.05" contype="0" conaffinity="0" rgba="0.1 0.85 0.1 1.0" pos="-1.4269183719899026 2.5528506689815575 0" /><geom type="sphere" size="0.05" contype="0" conaffinity="0" rgba="0.1 0.85 0.1 1.0" pos="-1.5021155776240422 2.1690125925031976 0" /><geom type="sphere" size="0.05" contype="0" conaffinity="0" rgba="0.1 0.85 0.1 1.0" pos="-1.5195321269267887 1.528546401049925 0" /><geom type="sphere" size="0.05" contype="0" conaffinity="0" rgba="0.1 0.85 0.1 1.0" pos="-1.498351556625378 0.8727323676180007 0" /><geom type="sphere" size="0.05" contype="0" conaffinity="0" rgba="0.1 0.85 0.1 1.0" pos="-1.4899225724059135 0.22974949787381596 0" /><geom type="sphere" size="0.05" contype="0" conaffinity="0" rgba="0.1 0.85 0.1 1.0" pos="-1.4959518068307964 -0.40549449744416777 0" /><geom type="sphere" size="0.05" contype="0" conaffinity="0" rgba="0.1 0.85 0.1 1.0" pos="-1.5032681913078547 -1.0430387465214555 0" /><geom type="sphere" size="0.05" contype="0" conaffinity="0" rgba="0.1 0.85 0.1 1.0" pos="-1.5047204054204169 -1.6872947766377784 0" /><geom type="sphere" size="0.05" contype="0" conaffinity="0" rgba="0.1 0.85 0.1 1.0" pos="-1.5000256689857536 -2.3366409849310514 0" /><geom type="sphere" size="0.05" contype="0" conaffinity="0" rgba="0.1 0.85 0.1 1.0" pos="-1.4957699991908109 -2.983422344668006 0" /><geom type="sphere" size="0.05" contype="0" conaffinity="0" rgba="0.1 0.85 0.1 1.0" pos="-1.5054082280862442 -3.6139503854905235 0" /></body><body name="ref_trajectory_body1" mocap="true" pos="0 0 0"><geom type="sphere" size="0.05" contype="0" conaffinity="0" rgba="0.8 0.5 0.1 1.0" pos="-1.5137496292455075 -3.606994046854743 0" /><geom type="sphere" size="0.05" contype="0" conaffinity="0" rgba="0.8 0.5 0.1 1.0" pos="-1.5043224958544583 -2.841100047563656 0" /><geom type="sphere" size="0.05" contype="0" conaffinity="0" rgba="0.8 0.5 0.1 1.0" pos="-1.5019861851773433 -2.061395078361718 0" /><geom type="sphere" size="0.05" contype="0" conaffinity="0" rgba="0.8 0.5 0.1 1.0" pos="-1.400276853577197 -1.6286994874370417 0" /><geom type="sphere" size="0.05" contype="0" conaffinity="0" rgba="0.8 0.5 0.1 1.0" pos="-1.1970929725818726 -1.2314686455870132 0" /><geom type="sphere" size="0.05" contype="0" conaffinity="0" rgba="0.8 0.5 0.1 1.0" pos="-0.8529181708187096 -0.8254829530522845 0" /><geom type="sphere" size="0.05" contype="0" conaffinity="0" rgba="0.8 0.5 0.1 1.0" pos="-0.40328044776921984 -0.41602106344611184 0" /><geom type="sphere" size="0.05" contype="0" conaffinity="0" rgba="0.8 0.5 0.1 1.0" pos="-0.023060165235576455 0.0018268404479461486 0" /></body></worldbody><contact><pair geom1="Fleet1Tenth_0_wheelfl" geom2="roundabout" condim="6" friction="2.5 2.5 .009 .0001 .0001" /><pair geom1="Fleet1Tenth_0_wheelfr" geom2="roundabout" condim="6" friction="2.5 2.5 .009 .0001 .0001" /><pair geom1="Fleet1Tenth_0_wheelrl" geom2="roundabout" condim="6" friction="2.5 2.5 .009 .0001 .0001" /><pair geom1="Fleet1Tenth_0_wheelrr" geom2="roundabout" condim="6" friction="2.5 2.5 .009 .0001 .0001" /><exclude name="car_marker_exc0" body1="Fleet1Tenth_0" body2="mpcc_0" /><exclude name="car_marker_exc1" body1="Fleet1Tenth_0" body2="mpcc_1" /><exclude name="car_marker_exc2" body1="Fleet1Tenth_0" body2="mpcc_2" /><exclude name="car_marker_exc3" body1="Fleet1Tenth_0" body2="mpcc_3" /><exclude name="car_marker_exc4" body1="Fleet1Tenth_0" body2="mpcc_4" /><exclude name="car_marker_exc5" body1="Fleet1Tenth_0" body2="mpcc_5" /><exclude name="car_marker_exc6" body1="Fleet1Tenth_0" body2="mpcc_6" /><exclude name="car_marker_exc7" body1="Fleet1Tenth_0" body2="mpcc_7" /><exclude name="car_marker_exc8" body1="Fleet1Tenth_0" body2="mpcc_8" /><exclude name="car_marker_exc9" body1="Fleet1Tenth_0" body2="mpcc_9" /><exclude name="car_marker_exc10" body1="Fleet1Tenth_0" body2="mpcc_10" /><exclude name="car_marker_exc11" body1="Fleet1Tenth_0" body2="mpcc_11" /><exclude name="car_marker_exc12" body1="Fleet1Tenth_0" body2="mpcc_12" /><exclude name="car_marker_exc13" body1="Fleet1Tenth_0" body2="mpcc_13" /><exclude name="car_marker_exc14" body1="Fleet1Tenth_0" body2="mpcc_14" /><exclude name="car_marker_exc15" body1="Fleet1Tenth_0" body2="mpcc_15" /><exclude name="car_marker_exc16" body1="Fleet1Tenth_0" body2="mpcc_16" /><exclude name="car_marker_exc17" body1="Fleet1Tenth_0" body2="mpcc_17" /><exclude name="car_marker_exc18" body1="Fleet1Tenth_0" body2="mpcc_18" /><exclude name="car_marker_exc19" body1="Fleet1Tenth_0" body2="mpcc_19" /><exclude name="marker_exclude0" body1="Fleet1Tenth_0" body2="ref_trajectory_body0" /><exclude name="marker_exclude1" body1="Fleet1Tenth_0" body2="ref_trajectory_body1" /></contact><actuator><motor name="Fleet1Tenth_0_wheelfl_actr" joint="Fleet1Tenth_0_wheelfl" /><motor name="Fleet1Tenth_0_wheelfr_actr" joint="Fleet1Tenth_0_wheelfr" /><motor name="Fleet1Tenth_0_wheelrl_actr" joint="Fleet1Tenth_0_wheelrl" /><motor name="Fleet1Tenth_0_wheelrr_actr" joint="Fleet1Tenth_0_wheelrr" /><position forcelimited="true" forcerange="-5 5" name="Fleet1Tenth_0_wheelfl_actr_steer" joint="Fleet1Tenth_0_wheelfl_steer" kp="15" /><position forcelimited="true" forcerange="-5 5" name="Fleet1Tenth_0_wheelfr_actr_steer" joint="Fleet1Tenth_0_wheelfr_steer" kp="15" /></actuator><sensor><gyro site="Fleet1Tenth_0_cog" name="Fleet1Tenth_0_gyro" /><velocimeter site="Fleet1Tenth_0_cog" name="Fleet1Tenth_0_velocimeter" /><framepos objtype="site" objname="Fleet1Tenth_0_cog" name="Fleet1Tenth_0_posimeter" /><framequat objtype="site" objname="Fleet1Tenth_0_cog" name="Fleet1Tenth_0_orimeter" /><accelerometer site="Fleet1Tenth_0_cog" name="Fleet1Tenth_0_accelerometer" /></sensor><option><flag contact="enable" /></option></mujoco>