<mujoco><include file="scene_without_walls.xml" /><worldbody><body name="Fleet1Tenth_0" pos="0 0 .052388" quat="0.9485664043524404 0 0 0.31657823130133655"><inertial pos="0 0 0" diaginertia=".05 .05 .08" mass="3.0" /><joint name="Fleet1Tenth_0" type="free" /><site name="Fleet1Tenth_0_cog" pos="0 0 0" /><geom name="Fleet1Tenth_0_chassis_b" type="box" size=".10113 .1016 .02" pos="-.06 0 0" rgba="0.85 0.2 0.2 1.0" /><geom name="Fleet1Tenth_0_chassis_f" type="box" size=".06 .07 .02" pos=".10113 0 0" rgba="0.85 0.2 0.2 1.0" /><geom name="Fleet1Tenth_0_front" type="box" size=".052388 .02 .02" pos=".2135 0 0" rgba="0.85 0.2 0.2 1.0" /><geom name="Fleet1Tenth_0_back" type="box" size=".052388 .02 .02" pos="-.2135 0 0" rgba="0.85 0.2 0.2 1.0" /><geom name="Fleet1Tenth_0_front_bumper" type="box" size=".005 .09 .02" pos=".265888 0 0.02" rgba="0.85 0.2 0.2 1.0" /><geom name="Fleet1Tenth_0_back_bumper" type="box" size=".005 .08 .02" pos="-.265888 0 0.02" rgba="0.85 0.2 0.2 1.0" /><geom name="Fleet1Tenth_0_number" type="cylinder" size=".01984 .03" pos=".12 0 .05" rgba="0.1 0.1 0.1 1.0" /><geom name="Fleet1Tenth_0_camera" type="box" size=".012 .06 0.02" pos=".18 0 .08" /><geom name="Fleet1Tenth_0_camera_holder" type="box" size=".012 .008 .02" pos=".18 0 .04" /><geom name="Fleet1Tenth_0_circuits" type="box" size=".08 .06 .03" pos="-.05 0 .05" rgba="0.85 0.2 0.2 1.0" /><geom name="Fleet1Tenth_0_antennal" type="box" size=".007 .004 .06" pos="-.16 -.01 .105" euler="0.2 0 0" rgba=".1 .1 .1 1.0" /><geom name="Fleet1Tenth_0_antennar" type="box" size=".007 .004 .06" pos="-.16 .01 .105" euler="-0.2 0 0" rgba=".1 .1 .1 1.0" /><geom name="Fleet1Tenth_0_antenna_holder" type="box" size=".008 .008 .02" pos="-.16 0 .04" rgba=".1 .1 .1 1.0" /><body name="Fleet1Tenth_0_wheelfl"><joint name="Fleet1Tenth_0_wheelfl_steer" type="hinge" pos="0.16113 .10016 0" limited="true" frictionloss="0.2" damping="0.2" armature="0.001" range="-0.6 0.6" axis="0 0 1" /><joint name="Fleet1Tenth_0_wheelfl" type="hinge" pos="0.16113 .122385 0" axis="0 1 0" frictionloss="0.01" damping="0.00001" armature="0.05" limited="false" /><geom name="Fleet1Tenth_0_wheelfl" type="cylinder" size=".052388 .022225" pos="0.16113 .122385 0" mass="0.1" material="material_check" euler="1.571 0 0" /></body><body name="Fleet1Tenth_0_wheelrl"><joint name="Fleet1Tenth_0_wheelrl" type="hinge" pos="-0.16113 .122385 0" axis="0 1 0" frictionloss="0.01" damping="0.00001" armature="0.05" limited="false" /><geom name="Fleet1Tenth_0_wheelrl" type="cylinder" size=".052388 .022225" pos="-0.16113 .122385 0" mass="0.1" material="material_check" euler="1.571 0 0" /></body><body name="Fleet1Tenth_0_wheelfr"><joint name="Fleet1Tenth_0_wheelfr_steer" type="hinge" pos="0.16113 -.10016 0" limited="true" frictionloss="0.2" damping="0.2" armature="0.001" range="-0.6 0.6" axis="0 0 1" /><joint name="Fleet1Tenth_0_wheelfr" type="hinge" pos="0.16113 -.122385 0" axis="0 1 0" frictionloss="0.01" damping="0.00001" armature="0.05" limited="false" /><geom name="Fleet1Tenth_0_wheelfr" type="cylinder" size=".052388 .022225" pos="0.16113 -.122385 0" mass="0.1" material="material_check" euler="1.571 0 0" /></body><body name="Fleet1Tenth_0_wheelrr"><joint name="Fleet1Tenth_0_wheelrr" type="hinge" pos="-0.16113 -.122385 0" axis="0 1 0" frictionloss="0.01" damping="0.00001" armature="0.05" limited="false" /><geom name="Fleet1Tenth_0_wheelrr" type="cylinder" size=".052388 .022225" pos="-0.16113 -.122385 0" mass="0.1" material="material_check" euler="1.571 0 0" /></body></body><body name="mpcc_0" pos="0 0 1" quat="0.9485664043524404 0 0 0.31657823130133655"><geom name="mpcc_marker0" type="sphere" size=".05" pos="0 0 0" rgba="0.2 0.2 0.85 1.0" /></body><body name="mpcc_1" pos="1 0 1" quat="0.9485664043524404 0 0 0.31657823130133655"><geom name="mpcc_marker1" type="sphere" size=".05" pos="0 0 0" rgba="0.2 0.2 0.85 1.0" /></body><body name="mpcc_2" pos="2 0 1" quat="0.9485664043524404 0 0 0.31657823130133655"><geom name="mpcc_marker2" type="sphere" size=".05" pos="0 0 0" rgba="0.2 0.2 0.85 1.0" /></body><body name="mpcc_3" pos="3 0 1" quat="0.9485664043524404 0 0 0.31657823130133655"><geom name="mpcc_marker3" type="sphere" size=".05" pos="0 0 0" rgba="0.2 0.2 0.85 1.0" /></body><body name="mpcc_4" pos="4 0 1" quat="0.9485664043524404 0 0 0.31657823130133655"><geom name="mpcc_marker4" type="sphere" size=".05" pos="0 0 0" rgba="0.2 0.2 0.85 1.0" /></body><body name="mpcc_5" pos="5 0 1" quat="0.9485664043524404 0 0 0.31657823130133655"><geom name="mpcc_marker5" type="sphere" size=".05" pos="0 0 0" rgba="0.2 0.2 0.85 1.0" /></body><body name="mpcc_6" pos="6 0 1" quat="0.9485664043524404 0 0 0.31657823130133655"><geom name="mpcc_marker6" type="sphere" size=".05" pos="0 0 0" rgba="0.2 0.2 0.85 1.0" /></body><body name="mpcc_7" pos="7 0 1" quat="0.9485664043524404 0 0 0.31657823130133655"><geom name="mpcc_marker7" type="sphere" size=".05" pos="0 0 0" rgba="0.2 0.2 0.85 1.0" /></body><body name="mpcc_8" pos="8 0 1" quat="0.9485664043524404 0 0 0.31657823130133655"><geom name="mpcc_marker8" type="sphere" size=".05" pos="0 0 0" rgba="0.2 0.2 0.85 1.0" /></body><body name="mpcc_9" pos="9 0 1" quat="0.9485664043524404 0 0 0.31657823130133655"><geom name="mpcc_marker9" type="sphere" size=".05" pos="0 0 0" rgba="0.2 0.2 0.85 1.0" /></body><body name="mpcc_10" pos="10 0 1" quat="0.9485664043524404 0 0 0.31657823130133655"><geom name="mpcc_marker10" type="sphere" size=".05" pos="0 0 0" rgba="0.2 0.2 0.85 1.0" /></body><body name="mpcc_11" pos="11 0 1" quat="0.9485664043524404 0 0 0.31657823130133655"><geom name="mpcc_marker11" type="sphere" size=".05" pos="0 0 0" rgba="0.2 0.2 0.85 1.0" /></body><body name="mpcc_12" pos="12 0 1" quat="0.9485664043524404 0 0 0.31657823130133655"><geom name="mpcc_marker12" type="sphere" size=".05" pos="0 0 0" rgba="0.2 0.2 0.85 1.0" /></body><body name="mpcc_13" pos="13 0 1" quat="0.9485664043524404 0 0 0.31657823130133655"><geom name="mpcc_marker13" type="sphere" size=".05" pos="0 0 0" rgba="0.2 0.2 0.85 1.0" /></body><body name="mpcc_14" pos="14 0 1" quat="0.9485664043524404 0 0 0.31657823130133655"><geom name="mpcc_marker14" type="sphere" size=".05" pos="0 0 0" rgba="0.2 0.2 0.85 1.0" /></body><body name="mpcc_15" pos="15 0 1" quat="0.9485664043524404 0 0 0.31657823130133655"><geom name="mpcc_marker15" type="sphere" size=".05" pos="0 0 0" rgba="0.2 0.2 0.85 1.0" /></body></worldbody><contact><pair geom1="Fleet1Tenth_0_wheelfl" geom2="roundabout" condim="6" friction="2.5 2.5 .009 .0001 .0001" /><pair geom1="Fleet1Tenth_0_wheelfr" geom2="roundabout" condim="6" friction="2.5 2.5 .009 .0001 .0001" /><pair geom1="Fleet1Tenth_0_wheelrl" geom2="roundabout" condim="6" friction="2.5 2.5 .009 .0001 .0001" /><pair geom1="Fleet1Tenth_0_wheelrr" geom2="roundabout" condim="6" friction="2.5 2.5 .009 .0001 .0001" /><exclude body1="Fleet1Tenth_0" body2="mpcc_0" /><exclude body1="Fleet1Tenth_0" body2="mpcc_1" /><exclude body1="Fleet1Tenth_0" body2="mpcc_2" /><exclude body1="Fleet1Tenth_0" body2="mpcc_3" /><exclude body1="Fleet1Tenth_0" body2="mpcc_4" /><exclude body1="Fleet1Tenth_0" body2="mpcc_5" /><exclude body1="Fleet1Tenth_0" body2="mpcc_6" /><exclude body1="Fleet1Tenth_0" body2="mpcc_7" /><exclude body1="Fleet1Tenth_0" body2="mpcc_8" /><exclude body1="Fleet1Tenth_0" body2="mpcc_9" /><exclude body1="Fleet1Tenth_0" body2="mpcc_10" /><exclude body1="Fleet1Tenth_0" body2="mpcc_11" /><exclude body1="Fleet1Tenth_0" body2="mpcc_12" /><exclude body1="Fleet1Tenth_0" body2="mpcc_13" /><exclude body1="Fleet1Tenth_0" body2="mpcc_14" /><exclude body1="Fleet1Tenth_0" body2="mpcc_15" /></contact><actuator><motor name="Fleet1Tenth_0_wheelfl_actr" joint="Fleet1Tenth_0_wheelfl" /><motor name="Fleet1Tenth_0_wheelfr_actr" joint="Fleet1Tenth_0_wheelfr" /><motor name="Fleet1Tenth_0_wheelrl_actr" joint="Fleet1Tenth_0_wheelrl" /><motor name="Fleet1Tenth_0_wheelrr_actr" joint="Fleet1Tenth_0_wheelrr" /><position forcelimited="true" forcerange="-5 5" name="Fleet1Tenth_0_wheelfl_actr_steer" joint="Fleet1Tenth_0_wheelfl_steer" kp="15" /><position forcelimited="true" forcerange="-5 5" name="Fleet1Tenth_0_wheelfr_actr_steer" joint="Fleet1Tenth_0_wheelfr_steer" kp="15" /></actuator><sensor><gyro site="Fleet1Tenth_0_cog" name="Fleet1Tenth_0_gyro" /><velocimeter site="Fleet1Tenth_0_cog" name="Fleet1Tenth_0_velocimeter" /><framepos objtype="site" objname="Fleet1Tenth_0_cog" name="Fleet1Tenth_0_posimeter" /><framequat objtype="site" objname="Fleet1Tenth_0_cog" name="Fleet1Tenth_0_orimeter" /><accelerometer site="Fleet1Tenth_0_cog" name="Fleet1Tenth_0_accelerometer" /></sensor></mujoco>